Workbook

Sheet Start Here
A1: Break-even & Funding Model
A2: Estimate how many paying customers and how much funding it takes to break even, and how to release money over time.
A4: HOW TO USE
A5: 1. Set your numbers | B5: On the Assumptions sheet, edit the blue numbers on yellow. Start with the Custom column, or overwrite any scenario.
A6: 2. Pick a scenario | B6: Assumptions cell B5 chooses which scenario the Model sheet shows in detail.
A7: 3. Read the Summary | B7: Key results for the selected scenario, funding tranches tied to the roadmap gates, and all five scenarios side by side with a chart.
A8: 4. Replace guesses | B8: After Phase 0, swap in real price, churn, and new-customer pace from your pilots and interviews.
A10: COLOUR LEGEND
A11: Blue on yellow | B11: An input you can change.
A12: Black | B12: A formula. Do not overwrite.
A13: Green | B13: A direct link to another sheet.
A15: SHEETS
A16: Summary | B16: Results, tranches, scenario comparison, chart.
A17: Assumptions | B17: All inputs, with a note on where each number came from.
A18: Model | B18: Month-by-month detail for the selected scenario over 60 months.
A19: Scenarios | B19: Calculation engine that runs all five scenarios so the Summary can compare them. Nothing to type.
A21: SOURCES AND ASSUMPTIONS
A22: Churn | B22: 3-7% monthly for SMB SaaS is cited in vendor benchmark articles (for example kalungi.com/blog/saas-churn-rate-benchmarks); a 2026 cohort study by Visionary Marketing reports a 4.7% median across SaaS. These are marketing-blog benchmarks, not landlord-specific data.
A23: SOC 2 | B23: A July 2026 breakdown (bdemerson.com/article/soc-2-cost) puts first-year SOC 2 at roughly $30k-$90k all in. Off by default.
A24: Competitor pricing | B24: Buildium (~$58-62/month) and DoorLoop (~$69/month) entry plans come from earlier research in this conversation. Verify current prices.
A25: Everything else | B25: Price, margin, acquisition cost, pace of new customers, fixed costs, and one-time costs are my placeholders [hypothesis]. Replace them with quotes and pilot data.
A27: NOT INCLUDED
A28: Excluded costs | B28: Developer payroll or contractor fees (enter them in 'Contractor / hired team'), the trust-accounting build and professional review, payment/bank/e-sign/screening integration fees, taxes, cost of capital, and the value of your own time.
A29: Simplifications | B29: One blended price for all customers; no annual prepay discounts or price changes; churn applied as a flat monthly rate; costs paid in the month incurred; 60-month window.
A30: Not advice | B30: Illustrative only. This is not financial advice; talk to a qualified advisor before raising or committing money.

Sheet Summary
A1: Break-even & Funding Summary
A2: ="Selected scenario: "&Assumptions!B5 -> Selected scenario: Base
A3: Illustrative outputs of placeholder assumptions, not forecasts and not financial advice.
A5: KEY RESULTS: SELECTED SCENARIO
A6: Contribution per customer per month ($) | B6: =Assumptions!B10*Assumptions!B11 -> 37.5 | C6: Price x gross margin.
A7: Total fixed costs per month ($) | B7: =Assumptions!B18 -> 5500
A8: Break-even customers, static | B8: =IFERROR(B7/B6,"-") -> 146.66667 | C8: Fixed costs / contribution. Ignores ongoing acquisition spend, so it understates the real target.
A9: Operating break-even month | B9: =IFERROR(INDEX(Model!$A$6:$A$65,MATCH(1,Model!$P$6:$P$65,0)),"Not reached in 60 months") -> 58 | C9: First month with net cash flow of zero or better (after growth starts).
A10: Customers at operating break-even | B10: =IFERROR(INDEX(Model!$E$6:$E$65,MATCH(1,Model!$P$6:$P$65,0)),"-") -> 200.41519
A11: Peak funding need ($) | B11: =-MIN(0,MIN(Model!$O$6:$O$65)) -> 202218.99 | C11: Deepest point of cumulative cash within 60 months.
A12: Month of peak funding need | B12: =IF(B11=0,"-",INDEX(Model!$A$6:$A$65,MATCH(MIN(Model!$O$6:$O$65),Model!$O$6:$O$65,0))) -> 57
A13: Buffer ($) | B13: =Assumptions!B41*B7 -> 22000 | C13: Buffer months x fixed costs.
A14: Suggested funding to line up ($) | B14: =B11+B13 -> 224218.99 | C14: Peak funding need plus buffer.
A15: Still losing cash at month 60? | B15: =IF(Model!N65<0,"Yes: peak is understated","No") -> No
A16: Customers at month 12 | B16: =INDEX(Model!$E$6:$E$65,12) -> 27.118296
A17: Customers at month 24 | B17: =INDEX(Model!$E$6:$E$65,24) -> 80.047351
A18: Customers at month 36 | B18: =INDEX(Model!$E$6:$E$65,36) -> 137.18228
A19: Customers at month 60 | B19: =INDEX(Model!$E$6:$E$65,60) -> 204.33065
A20: Steady-state customers (stage 3 pace / churn) | B20: =IFERROR(Assumptions!B29*Assumptions!B14/Assumptions!B12,"-") -> 266.66667 | C20: Customer counts level off near new customers per month / monthly churn.
A21: Acquisition cost payback (months) | B21: =IFERROR(Assumptions!B13/B6,"-") -> 6.6666667 | C21: Cash acquisition cost / contribution per month.
A22: Lifetime gross profit per customer ($) | B22: =IFERROR(B6/Assumptions!B12,"-") -> 1250 | C22: Contribution / monthly churn.
A23: Lifetime gross profit / acquisition cost | B23: =IFERROR(B22/Assumptions!B13,"-") -> 5 | C23: Rule of thumb some investors use is 3x or more; treat as a rough guide.
A25: FUNDING TRANCHES: SELECTED SCENARIO
A26: Tranche | B26: Net cash used ($) | C26: Cumulative cash at end ($) | D26: Roadmap phase and release gate
A27: ="Tranche 1: months 1-"&Assumptions!B42 -> Tranche 1: months 1-6 | B27: =-SUMIFS(Model!$N$6:$N$65,Model!$B$6:$B$65,1) -> 35256.75 | C27: =INDEX(Model!$O$6:$O$65,Assumptions!B42) -> -35256.75 | D27: Phase 0: pilot readiness and first pilots. Release: at the start.
A28: ="Tranche 2: months "&(Assumptions!B42+1)&"-"&Assumptions!B43 -> Tranche 2: months 7-12 | B28: =-SUMIFS(Model!$N$6:$N$65,Model!$B$6:$B$65,2) -> 47824.184 | C28: =INDEX(Model!$O$6:$O$65,Assumptions!B43) -> -83080.934 | D28: Phase 1: hosted option, legal and security reviews. Release: Phase 0 gate met (restore proven, pilots live, enough paid-pilot yeses).
A29: ="Tranche 3: months "&(Assumptions!B43+1)&"-"&Assumptions!B44 -> Tranche 3: months 13-24 | B29: =-SUMIFS(Model!$N$6:$N$65,Model!$B$6:$B$65,3) -> 58176.478 | C29: =INDEX(Model!$O$6:$O$65,Assumptions!B44) -> -141257.41 | D29: Phases 2-3: payments, phone and owner links. Release: churn near plan and new-customer pace on track.
A30: ="Tranche 4: months "&(Assumptions!B44+1)&"-"&Assumptions!B45 -> Tranche 4: months 25-36 | B30: =-SUMIFS(Model!$N$6:$N$65,Model!$B$6:$B$65,4) -> 39276.102 | C30: =INDEX(Model!$O$6:$O$65,Assumptions!B45) -> -180533.51 | D30: Phase 4 and toward break-even. Release: a visible path to break-even.
A31: ="Later: months "&(Assumptions!B45+1)&"-60" -> Later: months 37-60 | B31: =-SUMIFS(Model!$N$6:$N$65,Model!$B$6:$B$65,5) -> 21417.402 | C31: =INDEX(Model!$O$6:$O$65,60) -> -201950.92 | D31: Beyond the plan (Phases 5-6). Release: break-even reached, or re-plan.
A32: Total net cash used through month 60 | B32: =SUM(B27:B31) -> 201950.92
A33: Net cash used is positive when a tranche spends more than it earns (a negative number means a surplus). Cumulative cash is negative while you are funded by outside money.
A35: COMPARE ALL SCENARIOS
A36: Metric | B36: =Assumptions!C9 -> Conservative | C36: =Assumptions!D9 -> Base | D36: =Assumptions!E9 -> Optimistic | E36: =Assumptions!F9 -> Base - no founder draw | F36: =Assumptions!G9 -> Custom
A37: Blended price ($/month) | B37: =Assumptions!C10 -> 40 | C37: =Assumptions!D10 -> 50 | D37: =Assumptions!E10 -> 70 | E37: =Assumptions!F10 -> 50 | F37: =Assumptions!G10 -> 50
A38: Monthly churn | B38: =Assumptions!C12 -> 0.05 | C38: =Assumptions!D12 -> 0.03 | D38: =Assumptions!E12 -> 0.02 | E38: =Assumptions!F12 -> 0.03 | F38: =Assumptions!G12 -> 0.03
A39: New-customer pace multiplier | B39: =Assumptions!C14 -> 0.5 | C39: =Assumptions!D14 -> 1 | D39: =Assumptions!E14 -> 1.5 | E39: =Assumptions!F14 -> 1 | F39: =Assumptions!G14 -> 1
A40: Acquisition cost per new customer ($) | B40: =Assumptions!C13 -> 400 | C40: =Assumptions!D13 -> 250 | D40: =Assumptions!E13 -> 250 | E40: =Assumptions!F13 -> 250 | F40: =Assumptions!G13 -> 250
A41: Total fixed costs per month ($) | B41: =Assumptions!C18 -> 5500 | C41: =Assumptions!D18 -> 5500 | D41: =Assumptions!E18 -> 5500 | E41: =Assumptions!F18 -> 1500 | F41: =Assumptions!G18 -> 5500
A42: Break-even customers, static | B42: =IFERROR(Assumptions!C18/(Assumptions!C10*Assumptions!C11),"-") -> 183.33333 | C42: =IFERROR(Assumptions!D18/(Assumptions!D10*Assumptions!D11),"-") -> 146.66667 | D42: =IFERROR(Assumptions!E18/(Assumptions!E10*Assumptions!E11),"-") -> 104.7619 | E42: =IFERROR(Assumptions!F18/(Assumptions!F10*Assumptions!F11),"-") -> 40 | F42: =IFERROR(Assumptions!G18/(Assumptions!G10*Assumptions!G11),"-") -> 146.66667
A43: Operating break-even month | B43: =IFERROR(INDEX(Scenarios!$A$6:$A$65,MATCH(1,Scenarios!$G$6:$G$65,0)),"Not reached") -> Not reached | C43: =IFERROR(INDEX(Scenarios!$A$6:$A$65,MATCH(1,Scenarios!$L$6:$L$65,0)),"Not reached") -> 58 | D43: =IFERROR(INDEX(Scenarios!$A$6:$A$65,MATCH(1,Scenarios!$Q$6:$Q$65,0)),"Not reached") -> 28 | E43: =IFERROR(INDEX(Scenarios!$A$6:$A$65,MATCH(1,Scenarios!$V$6:$V$65,0)),"Not reached") -> 24 | F43: =IFERROR(INDEX(Scenarios!$A$6:$A$65,MATCH(1,Scenarios!$AA$6:$AA$65,0)),"Not reached") -> 58
...

Sheet Assumptions
A1: Assumptions
A2: Blue numbers on yellow are inputs. Every other sheet calculates from here. All figures are illustrative placeholders [hypothesis]: replace them with your own quotes and pilot data.
A4: SELECT SCENARIO (drives the Model sheet)
A5: Scenario shown on the Model sheet | B5: Base | C5: The Summary sheet compares all five scenarios at once; this choice only controls the detailed Model sheet.
A6: Scenario number | B6: =MATCH(B5,$C$9:$G$9,0) -> 2
A8: SCENARIO DRIVERS
A9: Driver | B9: Live (selected) | C9: Conservative | D9: Base | E9: Optimistic | F9: Base - no founder draw | G9: Custom | H9: Notes / source
A10: Blended price ($ per customer per month) | B10: =INDEX(C10:G10,$B$6) -> 50 | C10: 40 | D10: 50 | E10: 70 | F10: 50 | G10: 50 | H10: Base $50 is my assumption, a bit under the Buildium (~$58-62) and DoorLoop (~$69) entry plans from earlier research, since payments come later. Verify current competitor pricing.
A11: Gross margin (%) | B11: =INDEX(C11:G11,$B$6) -> 0.75 | C11: 0.75 | D11: 0.75 | E11: 0.75 | F11: 0.75 | G11: 0.75 | H11: My assumption for hosting, managed AI, and tools [hypothesis]. Payment-partner fees are treated as pass-through and excluded.
A12: Monthly customer churn (%) | B12: =INDEX(C12:G12,$B$6) -> 0.03 | C12: 0.05 | D12: 0.03 | E12: 0.02 | F12: 0.03 | G12: 0.03 | H12: Vendor benchmark articles cite 3-7% monthly for SMB SaaS; a 2026 cohort study reports a 4.7% median across SaaS. Small-landlord churn may differ. Replace with pilot data.
A13: Cash acquisition cost per new customer ($) | B13: =INDEX(C13:G13,$B$6) -> 250 | C13: 400 | D13: 250 | E13: 250 | F13: 250 | G13: 250 | H13: My assumption: gift cards, association fees, tools. Excludes your own time.
A14: New-customer pace multiplier (x) | B14: =INDEX(C14:G14,$B$6) -> 1 | C14: 0.5 | D14: 1 | E14: 1.5 | F14: 1 | G14: 1 | H14: Scales the pace table below (0.5x = half as many new customers per month).
A15: Founder draw ($ per month) | B15: =INDEX(C15:G15,$B$6) -> 4000 | C15: 4000 | D15: 4000 | E15: 4000 | F15: 0 | G15: 4000 | H15: Placeholder for living costs. Set to your own figure.
A16: Contractor / hired team ($ per month) | B16: =INDEX(C16:G16,$B$6) -> 0 | C16: 0 | D16: 0 | E16: 0 | F16: 0 | G16: 0 | H16: Zero in every scenario: developer costs are NOT included. Enter your real quotes here.
A17: Other fixed costs ($ per month) | B17: =INDEX(C17:G17,$B$6) -> 1500 | C17: 1500 | D17: 1500 | E17: 1500 | F17: 1500 | G17: 1500 | H17: My assumption: tools, hosting base, insurance, accounting, legal retainer, dev accounts.
A18: Total fixed costs ($ per month) | B18: =SUM(B15:B17) -> 5500 | C18: =SUM(C15:C17) -> 5500 | D18: =SUM(D15:D17) -> 5500 | E18: =SUM(E15:E17) -> 5500 | F18: =SUM(F15:F17) -> 1500 | G18: =SUM(G15:G17) -> 5500
A20: PACE OF NEW CUSTOMERS (before the scenario multiplier)
A21: Paying pilots | B21: 6 | C21: Interview plan: 5-10 paid pilots. Pilots are not scaled by the multiplier.
A22: Pilot start month | B22: 5 | C22: Months before this are build-only (no customers).
A23: Pilot setup fee ($ each, one time) | B23: 300 | C23: Pilot offer: 'a few hundred dollars' [hypothesis].
A24: First month of regular growth | B24: 7 | C24: Regular new-customer adds start here.
A25: New customers per month, stage 1 | B25: 4 | C25: My assumption for a solo founder using referrals and associations [hypothesis].
A26: Stage 1 ends after month | B26: 12
A27: New customers per month, stage 2 | B27: 6 | C27: My assumption [hypothesis].
A28: Stage 2 ends after month | B28: 24
A29: New customers per month, stage 3 (after stage 2) | B29: 8 | C29: My assumption [hypothesis].
A31: ONE-TIME COSTS
A32: Item | B32: Month | C32: Amount ($) | D32: Notes
A33: Incorporation, templates, initial legal | B33: 1 | C33: 3000 | D33: My placeholder [hypothesis]. Get quotes.
A34: Legal review (terms, privacy, state questions) | B34: 12 | C34: 8000 | D34: My placeholder [hypothesis]. Trust-accounting review before Phase 5 may cost more.
A35: Security testing | B35: 12 | C35: 5000 | D35: My placeholder [hypothesis].
A36: SOC 2 (optional, off by default) | B36: 24 | C36: 0 | D36: One 2026 breakdown puts first-year SOC 2 at roughly $30k-$90k all in. Enter an amount to include it.
A37: Other one-time (spare) | B37: 1 | C37: 0
A38: Other one-time (spare) | B38: 1 | C38: 0
A40: FUNDING PLAN
A41: Buffer (months of fixed costs) | B41: 4 | C41: Chat suggestion: 3-6 months.
A42: Tranche 1 ends after month | B42: 6 | C42: Roadmap Phase 0.
A43: Tranche 2 ends after month | B43: 12 | C43: Roadmap Phase 1.
A44: Tranche 3 ends after month | B44: 24 | C44: Roadmap Phases 2-3.
A45: Tranche 4 ends after month | B45: 36 | C45: Roadmap Phase 4 and toward break-even. Later months are shown as a fifth row.

Sheet Model
A1: Model: monthly detail for the selected scenario
A2: ="Scenario: "&Assumptions!B5&" (change it on the Assumptions sheet, cell B5)" -> Scenario: Base (change it on the Assumptions sheet, cell B5)
A4: Month | B4: Tranche | C4: New customers | D4: Churned customers | E4: Customers (end of month) | F4: Subscription revenue ($) | G4: Setup fees ($) | H4: Total revenue ($) | I4: Cost of service ($) | J4: Fixed costs ($) | K4: Acquisition spend ($) | L4: One-time costs ($) | M4: Total costs ($) | N4: Net cash flow ($) | O4: Cumulative cash ($) | P4: Break-even flag
A5: 0 | E5: 0 | O5: 0
A6: 1 | B6: =IF(A6<=Assumptions!$B$42,1,IF(A6<=Assumptions!$B$43,2,IF(A6<=Assumptions!$B$44,3,IF(A6<=Assumptions!$B$45,4,5)))) -> 1 | C6: =IF($A6=Assumptions!$B$22,Assumptions!$B$21,IF($A6<Assumptions!$B$24,0,IF($A6<=Assumptions!$B$26,Assumptions!$B$25,IF($A6<=Assumptions!$B$28,Assumptions!$B$27,Assumptions!$B$29))*Assumptions!$B$14)) -> 0 | D6: =E5*Assumptions!$B$12 -> 0 | E6: =E5-D6+C6 -> 0 | F6: =E6*Assumptions!$B$10 -> 0 | G6: =IF(A6=Assumptions!$B$22,Assumptions!$B$21*Assumptions!$B$23,0) -> 0 | H6: =F6+G6 -> 0 | I6: =F6*(1-Assumptions!$B$11) -> 0 | J6: =Assumptions!$B$18 -> 5500 | K6: =C6*Assumptions!$B$13 -> 0 | L6: =SUMIF(Assumptions!$B$33:$B$38,A6,Assumptions!$C$33:$C$38) -> 3000 | M6: =I6+J6+K6+L6 -> 8500 | N6: =H6-M6 -> -8500 | O6: =O5+N6 -> -8500 | P6: =IF(AND(A6>=Assumptions!$B$24,N6>=0),1,0) -> 0
A7: 2 | B7: =IF(A7<=Assumptions!$B$42,1,IF(A7<=Assumptions!$B$43,2,IF(A7<=Assumptions!$B$44,3,IF(A7<=Assumptions!$B$45,4,5)))) -> 1 | C7: =IF($A7=Assumptions!$B$22,Assumptions!$B$21,IF($A7<Assumptions!$B$24,0,IF($A7<=Assumptions!$B$26,Assumptions!$B$25,IF($A7<=Assumptions!$B$28,Assumptions!$B$27,Assumptions!$B$29))*Assumptions!$B$14)) -> 0 | D7: =E6*Assumptions!$B$12 -> 0 | E7: =E6-D7+C7 -> 0 | F7: =E7*Assumptions!$B$10 -> 0 | G7: =IF(A7=Assumptions!$B$22,Assumptions!$B$21*Assumptions!$B$23,0) -> 0 | H7: =F7+G7 -> 0 | I7: =F7*(1-Assumptions!$B$11) -> 0 | J7: =Assumptions!$B$18 -> 5500 | K7: =C7*Assumptions!$B$13 -> 0 | L7: =SUMIF(Assumptions!$B$33:$B$38,A7,Assumptions!$C$33:$C$38) -> 0 | M7: =I7+J7+K7+L7 -> 5500 | N7: =H7-M7 -> -5500 | O7: =O6+N7 -> -14000 | P7: =IF(AND(A7>=Assumptions!$B$24,N7>=0),1,0) -> 0
A8: 3 | B8: =IF(A8<=Assumptions!$B$42,1,IF(A8<=Assumptions!$B$43,2,IF(A8<=Assumptions!$B$44,3,IF(A8<=Assumptions!$B$45,4,5)))) -> 1 | C8: =IF($A8=Assumptions!$B$22,Assumptions!$B$21,IF($A8<Assumptions!$B$24,0,IF($A8<=Assumptions!$B$26,Assumptions!$B$25,IF($A8<=Assumptions!$B$28,Assumptions!$B$27,Assumptions!$B$29))*Assumptions!$B$14)) -> 0 | D8: =E7*Assumptions!$B$12 -> 0 | E8: =E7-D8+C8 -> 0 | F8: =E8*Assumptions!$B$10 -> 0 | G8: =IF(A8=Assumptions!$B$22,Assumptions!$B$21*Assumptions!$B$23,0) -> 0 | H8: =F8+G8 -> 0 | I8: =F8*(1-Assumptions!$B$11) -> 0 | J8: =Assumptions!$B$18 -> 5500 | K8: =C8*Assumptions!$B$13 -> 0 | L8: =SUMIF(Assumptions!$B$33:$B$38,A8,Assumptions!$C$33:$C$38) -> 0 | M8: =I8+J8+K8+L8 -> 5500 | N8: =H8-M8 -> -5500 | O8: =O7+N8 -> -19500 | P8: =IF(AND(A8>=Assumptions!$B$24,N8>=0),1,0) -> 0
A9: 4 | B9: =IF(A9<=Assumptions!$B$42,1,IF(A9<=Assumptions!$B$43,2,IF(A9<=Assumptions!$B$44,3,IF(A9<=Assumptions!$B$45,4,5)))) -> 1 | C9: =IF($A9=Assumptions!$B$22,Assumptions!$B$21,IF($A9<Assumptions!$B$24,0,IF($A9<=Assumptions!$B$26,Assumptions!$B$25,IF($A9<=Assumptions!$B$28,Assumptions!$B$27,Assumptions!$B$29))*Assumptions!$B$14)) -> 0 | D9: =E8*Assumptions!$B$12 -> 0 | E9: =E8-D9+C9 -> 0 | F9: =E9*Assumptions!$B$10 -> 0 | G9: =IF(A9=Assumptions!$B$22,Assumptions!$B$21*Assumptions!$B$23,0) -> 0 | H9: =F9+G9 -> 0 | I9: =F9*(1-Assumptions!$B$11) -> 0 | J9: =Assumptions!$B$18 -> 5500 | K9: =C9*Assumptions!$B$13 -> 0 | L9: =SUMIF(Assumptions!$B$33:$B$38,A9,Assumptions!$C$33:$C$38) -> 0 | M9: =I9+J9+K9+L9 -> 5500 | N9: =H9-M9 -> -5500 | O9: =O8+N9 -> -25000 | P9: =IF(AND(A9>=Assumptions!$B$24,N9>=0),1,0) -> 0
A10: 5 | B10: =IF(A10<=Assumptions!$B$42,1,IF(A10<=Assumptions!$B$43,2,IF(A10<=Assumptions!$B$44,3,IF(A10<=Assumptions!$B$45,4,5)))) -> 1 | C10: =IF($A10=Assumptions!$B$22,Assumptions!$B$21,IF($A10<Assumptions!$B$24,0,IF($A10<=Assumptions!$B$26,Assumptions!$B$25,IF($A10<=Assumptions!$B$28,Assumptions!$B$27,Assumptions!$B$29))*Assumptions!$B$14)) -> 6 | D10: =E9*Assumptions!$B$12 -> 0 | E10: =E9-D10+C10 -> 6 | F10: =E10*Assumptions!$B$10 -> 300 | G10: =IF(A10=Assumptions!$B$22,Assumptions!$B$21*Assumptions!$B$23,0) -> 1800 | H10: =F10+G10 -> 2100 | I10: =F10*(1-Assumptions!$B$11) -> 75 | J10: =Assumptions!$B$18 -> 5500 | K10: =C10*Assumptions!$B$13 -> 1500 | L10: =SUMIF(Assumptions!$B$33:$B$38,A10,Assumptions!$C$33:$C$38) -> 0 | M10: =I10+J10+K10+L10 -> 7075 | N10: =H10-M10 -> -4975 | O10: =O9+N10 -> -29975 | P10: =IF(AND(A10>=Assumptions!$B$24,N10>=0),1,0) -> 0
A11: 6 | B11: =IF(A11<=Assumptions!$B$42,1,IF(A11<=Assumptions!$B$43,2,IF(A11<=Assumptions!$B$44,3,IF(A11<=Assumptions!$B$45,4,5)))) -> 1 | C11: =IF($A11=Assumptions!$B$22,Assumptions!$B$21,IF($A11<Assumptions!$B$24,0,IF($A11<=Assumptions!$B$26,Assumptions!$B$25,IF($A11<=Assumptions!$B$28,Assumptions!$B$27,Assumptions!$B$29))*Assumptions!$B$14)) -> 0 | D11: =E10*Assumptions!$B$12 -> 0.18 | E11: =E10-D11+C11 -> 5.82 | F11: =E11*Assumptions!$B$10 -> 291 | G11: =IF(A11=Assumptions!$B$22,Assumptions!$B$21*Assumptions!$B$23,0) -> 0 | H11: =F11+G11 -> 291 | I11: =F11*(1-Assumptions!$B$11) -> 72.75 | J11: =Assumptions!$B$18 -> 5500 | K11: =C11*Assumptions!$B$13 -> 0 | L11: =SUMIF(Assumptions!$B$33:$B$38,A11,Assumptions!$C$33:$C$38) -> 0 | M11: =I11+J11+K11+L11 -> 5572.75 | N11: =H11-M11 -> -5281.75 | O11: =O10+N11 -> -35256.75 | P11: =IF(AND(A11>=Assumptions!$B$24,N11>=0),1,0) -> 0
A12: 7 | B12: =IF(A12<=Assumptions!$B$42,1,IF(A12<=Assumptions!$B$43,2,IF(A12<=Assumptions!$B$44,3,IF(A12<=Assumptions!$B$45,4,5)))) -> 2 | C12: =IF($A12=Assumptions!$B$22,Assumptions!$B$21,IF($A12<Assumptions!$B$24,0,IF($A12<=Assumptions!$B$26,Assumptions!$B$25,IF($A12<=Assumptions!$B$28,Assumptions!$B$27,Assumptions!$B$29))*Assumptions!$B$14)) -> 4 | D12: =E11*Assumptions!$B$12 -> 0.1746 | E12: =E11-D12+C12 -> 9.6454 | F12: =E12*Assumptions!$B$10 -> 482.27 | G12: =IF(A12=Assumptions!$B$22,Assumptions!$B$21*Assumptions!$B$23,0) -> 0 | H12: =F12+G12 -> 482.27 | I12: =F12*(1-Assumptions!$B$11) -> 120.5675 | J12: =Assumptions!$B$18 -> 5500 | K12: =C12*Assumptions!$B$13 -> 1000 | L12: =SUMIF(Assumptions!$B$33:$B$38,A12,Assumptions!$C$33:$C$38) -> 0 | M12: =I12+J12+K12+L12 -> 6620.5675 | N12: =H12-M12 -> -6138.2975 | O12: =O11+N12 -> -41395.048 | P12: =IF(AND(A12>=Assumptions!$B$24,N12>=0),1,0) -> 0
A13: 8 | B13: =IF(A13<=Assumptions!$B$42,1,IF(A13<=Assumptions!$B$43,2,IF(A13<=Assumptions!$B$44,3,IF(A13<=Assumptions!$B$45,4,5)))) -> 2 | C13: =IF($A13=Assumptions!$B$22,Assumptions!$B$21,IF($A13<Assumptions!$B$24,0,IF($A13<=Assumptions!$B$26,Assumptions!$B$25,IF($A13<=Assumptions!$B$28,Assumptions!$B$27,Assumptions!$B$29))*Assumptions!$B$14)) -> 4 | D13: =E12*Assumptions!$B$12 -> 0.289362 | E13: =E12-D13+C13 -> 13.356038 | F13: =E13*Assumptions!$B$10 -> 667.8019 | G13: =IF(A13=Assumptions!$B$22,Assumptions!$B$21*Assumptions!$B$23,0) -> 0 | H13: =F13+G13 -> 667.8019 | I13: =F13*(1-Assumptions!$B$11) -> 166.95048 | J13: =Assumptions!$B$18 -> 5500 | K13: =C13*Assumptions!$B$13 -> 1000 | L13: =SUMIF(Assumptions!$B$33:$B$38,A13,Assumptions!$C$33:$C$38) -> 0 | M13: =I13+J13+K13+L13 -> 6666.9505 | N13: =H13-M13 -> -5999.1486 | O13: =O12+N13 -> -47394.196 | P13: =IF(AND(A13>=Assumptions!$B$24,N13>=0),1,0) -> 0
A14: 9 | B14: =IF(A14<=Assumptions!$B$42,1,IF(A14<=Assumptions!$B$43,2,IF(A14<=Assumptions!$B$44,3,IF(A14<=Assumptions!$B$45,4,5)))) -> 2 | C14: =IF($A14=Assumptions!$B$22,Assumptions!$B$21,IF($A14<Assumptions!$B$24,0,IF($A14<=Assumptions!$B$26,Assumptions!$B$25,IF($A14<=Assumptions!$B$28,Assumptions!$B$27,Assumptions!$B$29))*Assumptions!$B$14)) -> 4 | D14: =E13*Assumptions!$B$12 -> 0.40068114 | E14: =E13-D14+C14 -> 16.955357 | F14: =E14*Assumptions!$B$10 -> 847.76784 | G14: =IF(A14=Assumptions!$B$22,Assumptions!$B$21*Assumptions!$B$23,0) -> 0 | H14: =F14+G14 -> 847.76784 | I14: =F14*(1-Assumptions!$B$11) -> 211.94196 | J14: =Assumptions!$B$18 -> 5500 | K14: =C14*Assumptions!$B$13 -> 1000 | L14: =SUMIF(Assumptions!$B$33:$B$38,A14,Assumptions!$C$33:$C$38) -> 0 | M14: =I14+J14+K14+L14 -> 6711.942 | N14: =H14-M14 -> -5864.1741 | O14: =O13+N14 -> -53258.37 | P14: =IF(AND(A14>=Assumptions!$B$24,N14>=0),1,0) -> 0
A15: 10 | B15: =IF(A15<=Assumptions!$B$42,1,IF(A15<=Assumptions!$B$43,2,IF(A15<=Assumptions!$B$44,3,IF(A15<=Assumptions!$B$45,4,5)))) -> 2 | C15: =IF($A15=Assumptions!$B$22,Assumptions!$B$21,IF($A15<Assumptions!$B$24,0,IF($A15<=Assumptions!$B$26,Assumptions!$B$25,IF($A15<=Assumptions!$B$28,Assumptions!$B$27,Assumptions!$B$29))*Assumptions!$B$14)) -> 4 | D15: =E14*Assumptions!$B$12 -> 0.50866071 | E15: =E14-D15+C15 -> 20.446696 | F15: =E15*Assumptions!$B$10 -> 1022.3348 | G15: =IF(A15=Assumptions!$B$22,Assumptions!$B$21*Assumptions!$B$23,0) -> 0 | H15: =F15+G15 -> 1022.3348 | I15: =F15*(1-Assumptions!$B$11) -> 255.5837 | J15: =Assumptions!$B$18 -> 5500 | K15: =C15*Assumptions!$B$13 -> 1000 | L15: =SUMIF(Assumptions!$B$33:$B$38,A15,Assumptions!$C$33:$C$38) -> 0 | M15: =I15+J15+K15+L15 -> 6755.5837 | N15: =H15-M15 -> -5733.2489 | O15: =O14+N15 -> -58991.619 | P15: =IF(AND(A15>=Assumptions!$B$24,N15>=0),1,0) -> 0
A16: 11 | B16: =IF(A16<=Assumptions!$B$42,1,IF(A16<=Assumptions!$B$43,2,IF(A16<=Assumptions!$B$44,3,IF(A16<=Assumptions!$B$45,4,5)))) -> 2 | C16: =IF($A16=Assumptions!$B$22,Assumptions!$B$21,IF($A16<Assumptions!$B$24,0,IF($A16<=Assumptions!$B$26,Assumptions!$B$25,IF($A16<=Assumptions!$B$28,Assumptions!$B$27,Assumptions!$B$29))*Assumptions!$B$14)) -> 4 | D16: =E15*Assumptions!$B$12 -> 0.61340088 | E16: =E15-D16+C16 -> 23.833295 | F16: =E16*Assumptions!$B$10 -> 1191.6648 | G16: =IF(A16=Assumptions!$B$22,Assumptions!$B$21*Assumptions!$B$23,0) -> 0 | H16: =F16+G16 -> 1191.6648 | I16: =F16*(1-Assumptions!$B$11) -> 297.91619 | J16: =Assumptions!$B$18 -> 5500 | K16: =C16*Assumptions!$B$13 -> 1000 | L16: =SUMIF(Assumptions!$B$33:$B$38,A16,Assumptions!$C$33:$C$38) -> 0 | M16: =I16+J16+K16+L16 -> 6797.9162 | N16: =H16-M16 -> -5606.2514 | O16: =O15+N16 -> -64597.871 | P16: =IF(AND(A16>=Assumptions!$B$24,N16>=0),1,0) -> 0
A17: 12 | B17: =IF(A17<=Assumptions!$B$42,1,IF(A17<=Assumptions!$B$43,2,IF(A17<=Assumptions!$B$44,3,IF(A17<=Assumptions!$B$45,4,5)))) -> 2 | C17: =IF($A17=Assumptions!$B$22,Assumptions!$B$21,IF($A17<Assumptions!$B$24,0,IF($A17<=Assumptions!$B$26,Assumptions!$B$25,IF($A17<=Assumptions!$B$28,Assumptions!$B$27,Assumptions!$B$29))*Assumptions!$B$14)) -> 4 | D17: =E16*Assumptions!$B$12 -> 0.71499886 | E17: =E16-D17+C17 -> 27.118296 | F17: =E17*Assumptions!$B$10 -> 1355.9148 | G17: =IF(A17=Assumptions!$B$22,Assumptions!$B$21*Assumptions!$B$23,0) -> 0 | H17: =F17+G17 -> 1355.9148 | I17: =F17*(1-Assumptions!$B$11) -> 338.97871 | J17: =Assumptions!$B$18 -> 5500 | K17: =C17*Assumptions!$B$13 -> 1000 | L17: =SUMIF(Assumptions!$B$33:$B$38,A17,Assumptions!$C$33:$C$38) -> 13000 | M17: =I17+J17+K17+L17 -> 19838.979 | N17: =H17-M17 -> -18483.064 | O17: =O16+N17 -> -83080.934 | P17: =IF(AND(A17>=Assumptions!$B$24,N17>=0),1,0) -> 0
... A65: 60 | B65: =IF(A65<=Assumptions!$B$42,1,IF(A65<=Assumptions!$B$43,2,IF(A65<=Assumptions!$B$44,3,IF(A65<=Assumptions!$B$45,4,5)))) -> 5 | C65: =IF($A65=Assumptions!$B$22,Assumptions!$B$21,IF($A65<Assumptions!$B$24,0,IF($A65<=Assumptions!$B$26,Assumptions!$B$25,IF($A65<=Assumptions!$B$28,Assumptions!$B$27,Assumptions!$B$29))*Assumptions!$B$14)) -> 8 | D65: =E64*Assumptions!$B$12 -> 6.072082 | E65: =E64-D65+C65 -> 204.33065 | F65: =E65*Assumptions!$B$10 -> 10216.533 | G65: =IF(A65=Assumptions!$B$22,Assumptions!$B$21*Assumptions!$B$23,0) -> 0 | H65: =F65+G65 -> 10216.533 | I65: =F65*(1-Assumptions!$B$11) -> 2554.1332 | J65: =Assumptions!$B$18 -> 5500 | K65: =C65*Assumptions!$B$13 -> 2000 | L65: =SUMIF(Assumptions!$B$33:$B$38,A65,Assumptions!$C$33:$C$38) -> 0 | M65: =I65+J65+K65+L65 -> 10054.133 | N65: =H65-M65 -> 162.39948 | O65: =O64+N65 -> -201950.92 | P65: =IF(AND(A65>=Assumptions!$B$24,N65>=0),1,0) -> 1
A67: Tranche 5 = months after the last tranche. The amber cell marks the point of peak funding need (lowest cumulative cash). The break-even flag is 1 when monthly net cash flow is zero or better from the first growth month on.

Sheet Scenarios
A1: Scenarios (calculation engine for all five scenarios)
A2: Nothing to type here. Each block repeats the Model logic for one scenario so the Summary can compare them live.
C3: =Assumptions!C9 -> Conservative | H3: =Assumptions!D9 -> Base | M3: =Assumptions!E9 -> Optimistic | R3: =Assumptions!F9 -> Base - no founder draw | W3: =Assumptions!G9 -> Custom
A4: Month | B4: One-time costs ($) | C4: New customers | D4: Customers | E4: Net cash flow ($) | F4: Cumulative cash ($) | G4: Break-even flag | H4: New customers | I4: Customers | J4: Net cash flow ($) | K4: Cumulative cash ($) | L4: Break-even flag | M4: New customers | N4: Customers | O4: Net cash flow ($) | P4: Cumulative cash ($) | Q4: Break-even flag | R4: New customers | S4: Customers | T4: Net cash flow ($) | U4: Cumulative cash ($) | V4: Break-even flag | W4: New customers | X4: Customers | Y4: Net cash flow ($) | Z4: Cumulative cash ($) | AA4: Break-even flag
A5: 0 | D5: 0 | F5: 0 | I5: 0 | K5: 0 | N5: 0 | P5: 0 | S5: 0 | U5: 0 | X5: 0 | Z5: 0
A6: 1 | B6: =SUMIF(Assumptions!$B$33:$B$38,A6,Assumptions!$C$33:$C$38) -> 3000 | C6: =IF($A6=Assumptions!$B$22,Assumptions!$B$21,IF($A6<Assumptions!$B$24,0,IF($A6<=Assumptions!$B$26,Assumptions!$B$25,IF($A6<=Assumptions!$B$28,Assumptions!$B$27,Assumptions!$B$29))*Assumptions!$C$14)) -> 0 | D6: =D5*(1-Assumptions!$C$12)+C6 -> 0 | E6: =D6*Assumptions!$C$10*Assumptions!$C$11+IF($A6=Assumptions!$B$22,Assumptions!$B$21*Assumptions!$B$23,0)-Assumptions!$C$18-C6*Assumptions!$C$13-$B6 -> -8500 | F6: =F5+E6 -> -8500 | G6: =IF(AND($A6>=Assumptions!$B$24,E6>=0),1,0) -> 0 | H6: =IF($A6=Assumptions!$B$22,Assumptions!$B$21,IF($A6<Assumptions!$B$24,0,IF($A6<=Assumptions!$B$26,Assumptions!$B$25,IF($A6<=Assumptions!$B$28,Assumptions!$B$27,Assumptions!$B$29))*Assumptions!$D$14)) -> 0 | I6: =I5*(1-Assumptions!$D$12)+H6 -> 0 | J6: =I6*Assumptions!$D$10*Assumptions!$D$11+IF($A6=Assumptions!$B$22,Assumptions!$B$21*Assumptions!$B$23,0)-Assumptions!$D$18-H6*Assumptions!$D$13-$B6 -> -8500 | K6: =K5+J6 -> -8500 | L6: =IF(AND($A6>=Assumptions!$B$24,J6>=0),1,0) -> 0 | M6: =IF($A6=Assumptions!$B$22,Assumptions!$B$21,IF($A6<Assumptions!$B$24,0,IF($A6<=Assumptions!$B$26,Assumptions!$B$25,IF($A6<=Assumptions!$B$28,Assumptions!$B$27,Assumptions!$B$29))*Assumptions!$E$14)) -> 0 | N6: =N5*(1-Assumptions!$E$12)+M6 -> 0 | O6: =N6*Assumptions!$E$10*Assumptions!$E$11+IF($A6=Assumptions!$B$22,Assumptions!$B$21*Assumptions!$B$23,0)-Assumptions!$E$18-M6*Assumptions!$E$13-$B6 -> -8500 | P6: =P5+O6 -> -8500 | Q6: =IF(AND($A6>=Assumptions!$B$24,O6>=0),1,0) -> 0 | R6: =IF($A6=Assumptions!$B$22,Assumptions!$B$21,IF($A6<Assumptions!$B$24,0,IF($A6<=Assumptions!$B$26,Assumptions!$B$25,IF($A6<=Assumptions!$B$28,Assumptions!$B$27,Assumptions!$B$29))*Assumptions!$F$14)) -> 0 | S6: =S5*(1-Assumptions!$F$12)+R6 -> 0 | T6: =S6*Assumptions!$F$10*Assumptions!$F$11+IF($A6=Assumptions!$B$22,Assumptions!$B$21*Assumptions!$B$23,0)-Assumptions!$F$18-R6*Assumptions!$F$13-$B6 -> -4500 | U6: =U5+T6 -> -4500 | V6: =IF(AND($A6>=Assumptions!$B$24,T6>=0),1,0) -> 0 | W6: =IF($A6=Assumptions!$B$22,Assumptions!$B$21,IF($A6<Assumptions!$B$24,0,IF($A6<=Assumptions!$B$26,Assumptions!$B$25,IF($A6<=Assumptions!$B$28,Assumptions!$B$27,Assumptions!$B$29))*Assumptions!$G$14)) -> 0 | X6: =X5*(1-Assumptions!$G$12)+W6 -> 0 | Y6: =X6*Assumptions!$G$10*Assumptions!$G$11+IF($A6=Assumptions!$B$22,Assumptions!$B$21*Assumptions!$B$23,0)-Assumptions!$G$18-W6*Assumptions!$G$13-$B6 -> -8500 | Z6: =Z5+Y6 -> -8500 | AA6: =IF(AND($A6>=Assumptions!$B$24,Y6>=0),1,0) -> 0
A7: 2 | B7: =SUMIF(Assumptions!$B$33:$B$38,A7,Assumptions!$C$33:$C$38) -> 0 | C7: =IF($A7=Assumptions!$B$22,Assumptions!$B$21,IF($A7<Assumptions!$B$24,0,IF($A7<=Assumptions!$B$26,Assumptions!$B$25,IF($A7<=Assumptions!$B$28,Assumptions!$B$27,Assumptions!$B$29))*Assumptions!$C$14)) -> 0 | D7: =D6*(1-Assumptions!$C$12)+C7 -> 0 | E7: =D7*Assumptions!$C$10*Assumptions!$C$11+IF($A7=Assumptions!$B$22,Assumptions!$B$21*Assumptions!$B$23,0)-Assumptions!$C$18-C7*Assumptions!$C$13-$B7 -> -5500 | F7: =F6+E7 -> -14000 | G7: =IF(AND($A7>=Assumptions!$B$24,E7>=0),1,0) -> 0 | H7: =IF($A7=Assumptions!$B$22,Assumptions!$B$21,IF($A7<Assumptions!$B$24,0,IF($A7<=Assumptions!$B$26,Assumptions!$B$25,IF($A7<=Assumptions!$B$28,Assumptions!$B$27,Assumptions!$B$29))*Assumptions!$D$14)) -> 0 | I7: =I6*(1-Assumptions!$D$12)+H7 -> 0 | J7: =I7*Assumptions!$D$10*Assumptions!$D$11+IF($A7=Assumptions!$B$22,Assumptions!$B$21*Assumptions!$B$23,0)-Assumptions!$D$18-H7*Assumptions!$D$13-$B7 -> -5500 | K7: =K6+J7 -> -14000 | L7: =IF(AND($A7>=Assumptions!$B$24,J7>=0),1,0) -> 0 | M7: =IF($A7=Assumptions!$B$22,Assumptions!$B$21,IF($A7<Assumptions!$B$24,0,IF($A7<=Assumptions!$B$26,Assumptions!$B$25,IF($A7<=Assumptions!$B$28,Assumptions!$B$27,Assumptions!$B$29))*Assumptions!$E$14)) -> 0 | N7: =N6*(1-Assumptions!$E$12)+M7 -> 0 | O7: =N7*Assumptions!$E$10*Assumptions!$E$11+IF($A7=Assumptions!$B$22,Assumptions!$B$21*Assumptions!$B$23,0)-Assumptions!$E$18-M7*Assumptions!$E$13-$B7 -> -5500 | P7: =P6+O7 -> -14000 | Q7: =IF(AND($A7>=Assumptions!$B$24,O7>=0),1,0) -> 0 | R7: =IF($A7=Assumptions!$B$22,Assumptions!$B$21,IF($A7<Assumptions!$B$24,0,IF($A7<=Assumptions!$B$26,Assumptions!$B$25,IF($A7<=Assumptions!$B$28,Assumptions!$B$27,Assumptions!$B$29))*Assumptions!$F$14)) -> 0 | S7: =S6*(1-Assumptions!$F$12)+R7 -> 0 | T7: =S7*Assumptions!$F$10*Assumptions!$F$11+IF($A7=Assumptions!$B$22,Assumptions!$B$21*Assumptions!$B$23,0)-Assumptions!$F$18-R7*Assumptions!$F$13-$B7 -> -1500 | U7: =U6+T7 -> -6000 | V7: =IF(AND($A7>=Assumptions!$B$24,T7>=0),1,0) -> 0 | W7: =IF($A7=Assumptions!$B$22,Assumptions!$B$21,IF($A7<Assumptions!$B$24,0,IF($A7<=Assumptions!$B$26,Assumptions!$B$25,IF($A7<=Assumptions!$B$28,Assumptions!$B$27,Assumptions!$B$29))*Assumptions!$G$14)) -> 0 | X7: =X6*(1-Assumptions!$G$12)+W7 -> 0 | Y7: =X7*Assumptions!$G$10*Assumptions!$G$11+IF($A7=Assumptions!$B$22,Assumptions!$B$21*Assumptions!$B$23,0)-Assumptions!$G$18-W7*Assumptions!$G$13-$B7 -> -5500 | Z7: =Z6+Y7 -> -14000 | AA7: =IF(AND($A7>=Assumptions!$B$24,Y7>=0),1,0) -> 0
A8: 3 | B8: =SUMIF(Assumptions!$B$33:$B$38,A8,Assumptions!$C$33:$C$38) -> 0 | C8: =IF($A8=Assumptions!$B$22,Assumptions!$B$21,IF($A8<Assumptions!$B$24,0,IF($A8<=Assumptions!$B$26,Assumptions!$B$25,IF($A8<=Assumptions!$B$28,Assumptions!$B$27,Assumptions!$B$29))*Assumptions!$C$14)) -> 0 | D8: =D7*(1-Assumptions!$C$12)+C8 -> 0 | E8: =D8*Assumptions!$C$10*Assumptions!$C$11+IF($A8=Assumptions!$B$22,Assumptions!$B$21*Assumptions!$B$23,0)-Assumptions!$C$18-C8*Assumptions!$C$13-$B8 -> -5500 | F8: =F7+E8 -> -19500 | G8: =IF(AND($A8>=Assumptions!$B$24,E8>=0),1,0) -> 0 | H8: =IF($A8=Assumptions!$B$22,Assumptions!$B$21,IF($A8<Assumptions!$B$24,0,IF($A8<=Assumptions!$B$26,Assumptions!$B$25,IF($A8<=Assumptions!$B$28,Assumptions!$B$27,Assumptions!$B$29))*Assumptions!$D$14)) -> 0 | I8: =I7*(1-Assumptions!$D$12)+H8 -> 0 | J8: =I8*Assumptions!$D$10*Assumptions!$D$11+IF($A8=Assumptions!$B$22,Assumptions!$B$21*Assumptions!$B$23,0)-Assumptions!$D$18-H8*Assumptions!$D$13-$B8 -> -5500 | K8: =K7+J8 -> -19500 | L8: =IF(AND($A8>=Assumptions!$B$24,J8>=0),1,0) -> 0 | M8: =IF($A8=Assumptions!$B$22,Assumptions!$B$21,IF($A8<Assumptions!$B$24,0,IF($A8<=Assumptions!$B$26,Assumptions!$B$25,IF($A8<=Assumptions!$B$28,Assumptions!$B$27,Assumptions!$B$29))*Assumptions!$E$14)) -> 0 | N8: =N7*(1-Assumptions!$E$12)+M8 -> 0 | O8: =N8*Assumptions!$E$10*Assumptions!$E$11+IF($A8=Assumptions!$B$22,Assumptions!$B$21*Assumptions!$B$23,0)-Assumptions!$E$18-M8*Assumptions!$E$13-$B8 -> -5500 | P8: =P7+O8 -> -19500 | Q8: =IF(AND($A8>=Assumptions!$B$24,O8>=0),1,0) -> 0 | R8: =IF($A8=Assumptions!$B$22,Assumptions!$B$21,IF($A8<Assumptions!$B$24,0,IF($A8<=Assumptions!$B$26,Assumptions!$B$25,IF($A8<=Assumptions!$B$28,Assumptions!$B$27,Assumptions!$B$29))*Assumptions!$F$14)) -> 0 | S8: =S7*(1-Assumptions!$F$12)+R8 -> 0 | T8: =S8*Assumptions!$F$10*Assumptions!$F$11+IF($A8=Assumptions!$B$22,Assumptions!$B$21*Assumptions!$B$23,0)-Assumptions!$F$18-R8*Assumptions!$F$13-$B8 -> -1500 | U8: =U7+T8 -> -7500 | V8: =IF(AND($A8>=Assumptions!$B$24,T8>=0),1,0) -> 0 | W8: =IF($A8=Assumptions!$B$22,Assumptions!$B$21,IF($A8<Assumptions!$B$24,0,IF($A8<=Assumptions!$B$26,Assumptions!$B$25,IF($A8<=Assumptions!$B$28,Assumptions!$B$27,Assumptions!$B$29))*Assumptions!$G$14)) -> 0 | X8: =X7*(1-Assumptions!$G$12)+W8 -> 0 | Y8: =X8*Assumptions!$G$10*Assumptions!$G$11+IF($A8=Assumptions!$B$22,Assumptions!$B$21*Assumptions!$B$23,0)-Assumptions!$G$18-W8*Assumptions!$G$13-$B8 -> -5500 | Z8: =Z7+Y8 -> -19500 | AA8: =IF(AND($A8>=Assumptions!$B$24,Y8>=0),1,0) -> 0
A9: 4 | B9: =SUMIF(Assumptions!$B$33:$B$38,A9,Assumptions!$C$33:$C$38) -> 0 | C9: =IF($A9=Assumptions!$B$22,Assumptions!$B$21,IF($A9<Assumptions!$B$24,0,IF($A9<=Assumptions!$B$26,Assumptions!$B$25,IF($A9<=Assumptions!$B$28,Assumptions!$B$27,Assumptions!$B$29))*Assumptions!$C$14)) -> 0 | D9: =D8*(1-Assumptions!$C$12)+C9 -> 0 | E9: =D9*Assumptions!$C$10*Assumptions!$C$11+IF($A9=Assumptions!$B$22,Assumptions!$B$21*Assumptions!$B$23,0)-Assumptions!$C$18-C9*Assumptions!$C$13-$B9 -> -5500 | F9: =F8+E9 -> -25000 | G9: =IF(AND($A9>=Assumptions!$B$24,E9>=0),1,0) -> 0 | H9: =IF($A9=Assumptions!$B$22,Assumptions!$B$21,IF($A9<Assumptions!$B$24,0,IF($A9<=Assumptions!$B$26,Assumptions!$B$25,IF($A9<=Assumptions!$B$28,Assumptions!$B$27,Assumptions!$B$29))*Assumptions!$D$14)) -> 0 | I9: =I8*(1-Assumptions!$D$12)+H9 -> 0 | J9: =I9*Assumptions!$D$10*Assumptions!$D$11+IF($A9=Assumptions!$B$22,Assumptions!$B$21*Assumptions!$B$23,0)-Assumptions!$D$18-H9*Assumptions!$D$13-$B9 -> -5500 | K9: =K8+J9 -> -25000 | L9: =IF(AND($A9>=Assumptions!$B$24,J9>=0),1,0) -> 0 | M9: =IF($A9=Assumptions!$B$22,Assumptions!$B$21,IF($A9<Assumptions!$B$24,0,IF($A9<=Assumptions!$B$26,Assumptions!$B$25,IF($A9<=Assumptions!$B$28,Assumptions!$B$27,Assumptions!$B$29))*Assumptions!$E$14)) -> 0 | N9: =N8*(1-Assumptions!$E$12)+M9 -> 0 | O9: =N9*Assumptions!$E$10*Assumptions!$E$11+IF($A9=Assumptions!$B$22,Assumptions!$B$21*Assumptions!$B$23,0)-Assumptions!$E$18-M9*Assumptions!$E$13-$B9 -> -5500 | P9: =P8+O9 -> -25000 | Q9: =IF(AND($A9>=Assumptions!$B$24,O9>=0),1,0) -> 0 | R9: =IF($A9=Assumptions!$B$22,Assumptions!$B$21,IF($A9<Assumptions!$B$24,0,IF($A9<=Assumptions!$B$26,Assumptions!$B$25,IF($A9<=Assumptions!$B$28,Assumptions!$B$27,Assumptions!$B$29))*Assumptions!$F$14)) -> 0 | S9: =S8*(1-Assumptions!$F$12)+R9 -> 0 | T9: =S9*Assumptions!$F$10*Assumptions!$F$11+IF($A9=Assumptions!$B$22,Assumptions!$B$21*Assumptions!$B$23,0)-Assumptions!$F$18-R9*Assumptions!$F$13-$B9 -> -1500 | U9: =U8+T9 -> -9000 | V9: =IF(AND($A9>=Assumptions!$B$24,T9>=0),1,0) -> 0 | W9: =IF($A9=Assumptions!$B$22,Assumptions!$B$21,IF($A9<Assumptions!$B$24,0,IF($A9<=Assumptions!$B$26,Assumptions!$B$25,IF($A9<=Assumptions!$B$28,Assumptions!$B$27,Assumptions!$B$29))*Assumptions!$G$14)) -> 0 | X9: =X8*(1-Assumptions!$G$12)+W9 -> 0 | Y9: =X9*Assumptions!$G$10*Assumptions!$G$11+IF($A9=Assumptions!$B$22,Assumptions!$B$21*Assumptions!$B$23,0)-Assumptions!$G$18-W9*Assumptions!$G$13-$B9 -> -5500 | Z9: =Z8+Y9 -> -25000 | AA9: =IF(AND($A9>=Assumptions!$B$24,Y9>=0),1,0) -> 0
A10: 5 | B10: =SUMIF(Assumptions!$B$33:$B$38,A10,Assumptions!$C$33:$C$38) -> 0 | C10: =IF($A10=Assumptions!$B$22,Assumptions!$B$21,IF($A10<Assumptions!$B$24,0,IF($A10<=Assumptions!$B$26,Assumptions!$B$25,IF($A10<=Assumptions!$B$28,Assumptions!$B$27,Assumptions!$B$29))*Assumptions!$C$14)) -> 6 | D10: =D9*(1-Assumptions!$C$12)+C10 -> 6 | E10: =D10*Assumptions!$C$10*Assumptions!$C$11+IF($A10=Assumptions!$B$22,Assumptions!$B$21*Assumptions!$B$23,0)-Assumptions!$C$18-C10*Assumptions!$C$13-$B10 -> -5920 | F10: =F9+E10 -> -30920 | G10: =IF(AND($A10>=Assumptions!$B$24,E10>=0),1,0) -> 0 | H10: =IF($A10=Assumptions!$B$22,Assumptions!$B$21,IF($A10<Assumptions!$B$24,0,IF($A10<=Assumptions!$B$26,Assumptions!$B$25,IF($A10<=Assumptions!$B$28,Assumptions!$B$27,Assumptions!$B$29))*Assumptions!$D$14)) -> 6 | I10: =I9*(1-Assumptions!$D$12)+H10 -> 6 | J10: =I10*Assumptions!$D$10*Assumptions!$D$11+IF($A10=Assumptions!$B$22,Assumptions!$B$21*Assumptions!$B$23,0)-Assumptions!$D$18-H10*Assumptions!$D$13-$B10 -> -4975 | K10: =K9+J10 -> -29975 | L10: =IF(AND($A10>=Assumptions!$B$24,J10>=0),1,0) -> 0 | M10: =IF($A10=Assumptions!$B$22,Assumptions!$B$21,IF($A10<Assumptions!$B$24,0,IF($A10<=Assumptions!$B$26,Assumptions!$B$25,IF($A10<=Assumptions!$B$28,Assumptions!$B$27,Assumptions!$B$29))*Assumptions!$E$14)) -> 6 | N10: =N9*(1-Assumptions!$E$12)+M10 -> 6 | O10: =N10*Assumptions!$E$10*Assumptions!$E$11+IF($A10=Assumptions!$B$22,Assumptions!$B$21*Assumptions!$B$23,0)-Assumptions!$E$18-M10*Assumptions!$E$13-$B10 -> -4885 | P10: =P9+O10 -> -29885 | Q10: =IF(AND($A10>=Assumptions!$B$24,O10>=0),1,0) -> 0 | R10: =IF($A10=Assumptions!$B$22,Assumptions!$B$21,IF($A10<Assumptions!$B$24,0,IF($A10<=Assumptions!$B$26,Assumptions!$B$25,IF($A10<=Assumptions!$B$28,Assumptions!$B$27,Assumptions!$B$29))*Assumptions!$F$14)) -> 6 | S10: =S9*(1-Assumptions!$F$12)+R10 -> 6 | T10: =S10*Assumptions!$F$10*Assumptions!$F$11+IF($A10=Assumptions!$B$22,Assumptions!$B$21*Assumptions!$B$23,0)-Assumptions!$F$18-R10*Assumptions!$F$13-$B10 -> -975 | U10: =U9+T10 -> -9975 | V10: =IF(AND($A10>=Assumptions!$B$24,T10>=0),1,0) -> 0 | W10: =IF($A10=Assumptions!$B$22,Assumptions!$B$21,IF($A10<Assumptions!$B$24,0,IF($A10<=Assumptions!$B$26,Assumptions!$B$25,IF($A10<=Assumptions!$B$28,Assumptions!$B$27,Assumptions!$B$29))*Assumptions!$G$14)) -> 6 | X10: =X9*(1-Assumptions!$G$12)+W10 -> 6 | Y10: =X10*Assumptions!$G$10*Assumptions!$G$11+IF($A10=Assumptions!$B$22,Assumptions!$B$21*Assumptions!$B$23,0)-Assumptions!$G$18-W10*Assumptions!$G$13-$B10 -> -4975 | Z10: =Z9+Y10 -> -29975 | AA10: =IF(AND($A10>=Assumptions!$B$24,Y10>=0),1,0) -> 0
A11: 6 | B11: =SUMIF(Assumptions!$B$33:$B$38,A11,Assumptions!$C$33:$C$38) -> 0 | C11: =IF($A11=Assumptions!$B$22,Assumptions!$B$21,IF($A11<Assumptions!$B$24,0,IF($A11<=Assumptions!$B$26,Assumptions!$B$25,IF($A11<=Assumptions!$B$28,Assumptions!$B$27,Assumptions!$B$29))*Assumptions!$C$14)) -> 0 | D11: =D10*(1-Assumptions!$C$12)+C11 -> 5.7 | E11: =D11*Assumptions!$C$10*Assumptions!$C$11+IF($A11=Assumptions!$B$22,Assumptions!$B$21*Assumptions!$B$23,0)-Assumptions!$C$18-C11*Assumptions!$C$13-$B11 -> -5329 | F11: =F10+E11 -> -36249 | G11: =IF(AND($A11>=Assumptions!$B$24,E11>=0),1,0) -> 0 | H11: =IF($A11=Assumptions!$B$22,Assumptions!$B$21,IF($A11<Assumptions!$B$24,0,IF($A11<=Assumptions!$B$26,Assumptions!$B$25,IF($A11<=Assumptions!$B$28,Assumptions!$B$27,Assumptions!$B$29))*Assumptions!$D$14)) -> 0 | I11: =I10*(1-Assumptions!$D$12)+H11 -> 5.82 | J11: =I11*Assumptions!$D$10*Assumptions!$D$11+IF($A11=Assumptions!$B$22,Assumptions!$B$21*Assumptions!$B$23,0)-Assumptions!$D$18-H11*Assumptions!$D$13-$B11 -> -5281.75 | K11: =K10+J11 -> -35256.75 | L11: =IF(AND($A11>=Assumptions!$B$24,J11>=0),1,0) -> 0 | M11: =IF($A11=Assumptions!$B$22,Assumptions!$B$21,IF($A11<Assumptions!$B$24,0,IF($A11<=Assumptions!$B$26,Assumptions!$B$25,IF($A11<=Assumptions!$B$28,Assumptions!$B$27,Assumptions!$B$29))*Assumptions!$E$14)) -> 0 | N11: =N10*(1-Assumptions!$E$12)+M11 -> 5.88 | O11: =N11*Assumptions!$E$10*Assumptions!$E$11+IF($A11=Assumptions!$B$22,Assumptions!$B$21*Assumptions!$B$23,0)-Assumptions!$E$18-M11*Assumptions!$E$13-$B11 -> -5191.3 | P11: =P10+O11 -> -35076.3 | Q11: =IF(AND($A11>=Assumptions!$B$24,O11>=0),1,0) -> 0 | R11: =IF($A11=Assumptions!$B$22,Assumptions!$B$21,IF($A11<Assumptions!$B$24,0,IF($A11<=Assumptions!$B$26,Assumptions!$B$25,IF($A11<=Assumptions!$B$28,Assumptions!$B$27,Assumptions!$B$29))*Assumptions!$F$14)) -> 0 | S11: =S10*(1-Assumptions!$F$12)+R11 -> 5.82 | T11: =S11*Assumptions!$F$10*Assumptions!$F$11+IF($A11=Assumptions!$B$22,Assumptions!$B$21*Assumptions!$B$23,0)-Assumptions!$F$18-R11*Assumptions!$F$13-$B11 -> -1281.75 | U11: =U10+T11 -> -11256.75 | V11: =IF(AND($A11>=Assumptions!$B$24,T11>=0),1,0) -> 0 | W11: =IF($A11=Assumptions!$B$22,Assumptions!$B$21,IF($A11<Assumptions!$B$24,0,IF($A11<=Assumptions!$B$26,Assumptions!$B$25,IF($A11<=Assumptions!$B$28,Assumptions!$B$27,Assumptions!$B$29))*Assumptions!$G$14)) -> 0 | X11: =X10*(1-Assumptions!$G$12)+W11 -> 5.82 | Y11: =X11*Assumptions!$G$10*Assumptions!$G$11+IF($A11=Assumptions!$B$22,Assumptions!$B$21*Assumptions!$B$23,0)-Assumptions!$G$18-W11*Assumptions!$G$13-$B11 -> -5281.75 | Z11: =Z10+Y11 -> -35256.75 | AA11: =IF(AND($A11>=Assumptions!$B$24,Y11>=0),1,0) -> 0
A12: 7 | B12: =SUMIF(Assumptions!$B$33:$B$38,A12,Assumptions!$C$33:$C$38) -> 0 | C12: =IF($A12=Assumptions!$B$22,Assumptions!$B$21,IF($A12<Assumptions!$B$24,0,IF($A12<=Assumptions!$B$26,Assumptions!$B$25,IF($A12<=Assumptions!$B$28,Assumptions!$B$27,Assumptions!$B$29))*Assumptions!$C$14)) -> 2 | D12: =D11*(1-Assumptions!$C$12)+C12 -> 7.415 | E12: =D12*Assumptions!$C$10*Assumptions!$C$11+IF($A12=Assumptions!$B$22,Assumptions!$B$21*Assumptions!$B$23,0)-Assumptions!$C$18-C12*Assumptions!$C$13-$B12 -> -6077.55 | F12: =F11+E12 -> -42326.55 | G12: =IF(AND($A12>=Assumptions!$B$24,E12>=0),1,0) -> 0 | H12: =IF($A12=Assumptions!$B$22,Assumptions!$B$21,IF($A12<Assumptions!$B$24,0,IF($A12<=Assumptions!$B$26,Assumptions!$B$25,IF($A12<=Assumptions!$B$28,Assumptions!$B$27,Assumptions!$B$29))*Assumptions!$D$14)) -> 4 | I12: =I11*(1-Assumptions!$D$12)+H12 -> 9.6454 | J12: =I12*Assumptions!$D$10*Assumptions!$D$11+IF($A12=Assumptions!$B$22,Assumptions!$B$21*Assumptions!$B$23,0)-Assumptions!$D$18-H12*Assumptions!$D$13-$B12 -> -6138.2975 | K12: =K11+J12 -> -41395.048 | L12: =IF(AND($A12>=Assumptions!$B$24,J12>=0),1,0) -> 0 | M12: =IF($A12=Assumptions!$B$22,Assumptions!$B$21,IF($A12<Assumptions!$B$24,0,IF($A12<=Assumptions!$B$26,Assumptions!$B$25,IF($A12<=Assumptions!$B$28,Assumptions!$B$27,Assumptions!$B$29))*Assumptions!$E$14)) -> 6 | N12: =N11*(1-Assumptions!$E$12)+M12 -> 11.7624 | O12: =N12*Assumptions!$E$10*Assumptions!$E$11+IF($A12=Assumptions!$B$22,Assumptions!$B$21*Assumptions!$B$23,0)-Assumptions!$E$18-M12*Assumptions!$E$13-$B12 -> -6382.474 | P12: =P11+O12 -> -41458.774 | Q12: =IF(AND($A12>=Assumptions!$B$24,O12>=0),1,0) -> 0 | R12: =IF($A12=Assumptions!$B$22,Assumptions!$B$21,IF($A12<Assumptions!$B$24,0,IF($A12<=Assumptions!$B$26,Assumptions!$B$25,IF($A12<=Assumptions!$B$28,Assumptions!$B$27,Assumptions!$B$29))*Assumptions!$F$14)) -> 4 | S12: =S11*(1-Assumptions!$F$12)+R12 -> 9.6454 | T12: =S12*Assumptions!$F$10*Assumptions!$F$11+IF($A12=Assumptions!$B$22,Assumptions!$B$21*Assumptions!$B$23,0)-Assumptions!$F$18-R12*Assumptions!$F$13-$B12 -> -2138.2975 | U12: =U11+T12 -> -13395.048 | V12: =IF(AND($A12>=Assumptions!$B$24,T12>=0),1,0) -> 0 | W12: =IF($A12=Assumptions!$B$22,Assumptions!$B$21,IF($A12<Assumptions!$B$24,0,IF($A12<=Assumptions!$B$26,Assumptions!$B$25,IF($A12<=Assumptions!$B$28,Assumptions!$B$27,Assumptions!$B$29))*Assumptions!$G$14)) -> 4 | X12: =X11*(1-Assumptions!$G$12)+W12 -> 9.6454 | Y12: =X12*Assumptions!$G$10*Assumptions!$G$11+IF($A12=Assumptions!$B$22,Assumptions!$B$21*Assumptions!$B$23,0)-Assumptions!$G$18-W12*Assumptions!$G$13-$B12 -> -6138.2975 | Z12: =Z11+Y12 -> -41395.048 | AA12: =IF(AND($A12>=Assumptions!$B$24,Y12>=0),1,0) -> 0
A13: 8 | B13: =SUMIF(Assumptions!$B$33:$B$38,A13,Assumptions!$C$33:$C$38) -> 0 | C13: =IF($A13=Assumptions!$B$22,Assumptions!$B$21,IF($A13<Assumptions!$B$24,0,IF($A13<=Assumptions!$B$26,Assumptions!$B$25,IF($A13<=Assumptions!$B$28,Assumptions!$B$27,Assumptions!$B$29))*Assumptions!$C$14)) -> 2 | D13: =D12*(1-Assumptions!$C$12)+C13 -> 9.04425 | E13: =D13*Assumptions!$C$10*Assumptions!$C$11+IF($A13=Assumptions!$B$22,Assumptions!$B$21*Assumptions!$B$23,0)-Assumptions!$C$18-C13*Assumptions!$C$13-$B13 -> -6028.6725 | F13: =F12+E13 -> -48355.223 | G13: =IF(AND($A13>=Assumptions!$B$24,E13>=0),1,0) -> 0 | H13: =IF($A13=Assumptions!$B$22,Assumptions!$B$21,IF($A13<Assumptions!$B$24,0,IF($A13<=Assumptions!$B$26,Assumptions!$B$25,IF($A13<=Assumptions!$B$28,Assumptions!$B$27,Assumptions!$B$29))*Assumptions!$D$14)) -> 4 | I13: =I12*(1-Assumptions!$D$12)+H13 -> 13.356038 | J13: =I13*Assumptions!$D$10*Assumptions!$D$11+IF($A13=Assumptions!$B$22,Assumptions!$B$21*Assumptions!$B$23,0)-Assumptions!$D$18-H13*Assumptions!$D$13-$B13 -> -5999.1486 | K13: =K12+J13 -> -47394.196 | L13: =IF(AND($A13>=Assumptions!$B$24,J13>=0),1,0) -> 0 | M13: =IF($A13=Assumptions!$B$22,Assumptions!$B$21,IF($A13<Assumptions!$B$24,0,IF($A13<=Assumptions!$B$26,Assumptions!$B$25,IF($A13<=Assumptions!$B$28,Assumptions!$B$27,Assumptions!$B$29))*Assumptions!$E$14)) -> 6 | N13: =N12*(1-Assumptions!$E$12)+M13 -> 17.527152 | O13: =N13*Assumptions!$E$10*Assumptions!$E$11+IF($A13=Assumptions!$B$22,Assumptions!$B$21*Assumptions!$B$23,0)-Assumptions!$E$18-M13*Assumptions!$E$13-$B13 -> -6079.8245 | P13: =P12+O13 -> -47538.599 | Q13: =IF(AND($A13>=Assumptions!$B$24,O13>=0),1,0) -> 0 | R13: =IF($A13=Assumptions!$B$22,Assumptions!$B$21,IF($A13<Assumptions!$B$24,0,IF($A13<=Assumptions!$B$26,Assumptions!$B$25,IF($A13<=Assumptions!$B$28,Assumptions!$B$27,Assumptions!$B$29))*Assumptions!$F$14)) -> 4 | S13: =S12*(1-Assumptions!$F$12)+R13 -> 13.356038 | T13: =S13*Assumptions!$F$10*Assumptions!$F$11+IF($A13=Assumptions!$B$22,Assumptions!$B$21*Assumptions!$B$23,0)-Assumptions!$F$18-R13*Assumptions!$F$13-$B13 -> -1999.1486 | U13: =U12+T13 -> -15394.196 | V13: =IF(AND($A13>=Assumptions!$B$24,T13>=0),1,0) -> 0 | W13: =IF($A13=Assumptions!$B$22,Assumptions!$B$21,IF($A13<Assumptions!$B$24,0,IF($A13<=Assumptions!$B$26,Assumptions!$B$25,IF($A13<=Assumptions!$B$28,Assumptions!$B$27,Assumptions!$B$29))*Assumptions!$G$14)) -> 4 | X13: =X12*(1-Assumptions!$G$12)+W13 -> 13.356038 | Y13: =X13*Assumptions!$G$10*Assumptions!$G$11+IF($A13=Assumptions!$B$22,Assumptions!$B$21*Assumptions!$B$23,0)-Assumptions!$G$18-W13*Assumptions!$G$13-$B13 -> -5999.1486 | Z13: =Z12+Y13 -> -47394.196 | AA13: =IF(AND($A13>=Assumptions!$B$24,Y13>=0),1,0) -> 0
A14: 9 | B14: =SUMIF(Assumptions!$B$33:$B$38,A14,Assumptions!$C$33:$C$38) -> 0 | C14: =IF($A14=Assumptions!$B$22,Assumptions!$B$21,IF($A14<Assumptions!$B$24,0,IF($A14<=Assumptions!$B$26,Assumptions!$B$25,IF($A14<=Assumptions!$B$28,Assumptions!$B$27,Assumptions!$B$29))*Assumptions!$C$14)) -> 2 | D14: =D13*(1-Assumptions!$C$12)+C14 -> 10.592037 | E14: =D14*Assumptions!$C$10*Assumptions!$C$11+IF($A14=Assumptions!$B$22,Assumptions!$B$21*Assumptions!$B$23,0)-Assumptions!$C$18-C14*Assumptions!$C$13-$B14 -> -5982.2389 | F14: =F13+E14 -> -54337.461 | G14: =IF(AND($A14>=Assumptions!$B$24,E14>=0),1,0) -> 0 | H14: =IF($A14=Assumptions!$B$22,Assumptions!$B$21,IF($A14<Assumptions!$B$24,0,IF($A14<=Assumptions!$B$26,Assumptions!$B$25,IF($A14<=Assumptions!$B$28,Assumptions!$B$27,Assumptions!$B$29))*Assumptions!$D$14)) -> 4 | I14: =I13*(1-Assumptions!$D$12)+H14 -> 16.955357 | J14: =I14*Assumptions!$D$10*Assumptions!$D$11+IF($A14=Assumptions!$B$22,Assumptions!$B$21*Assumptions!$B$23,0)-Assumptions!$D$18-H14*Assumptions!$D$13-$B14 -> -5864.1741 | K14: =K13+J14 -> -53258.37 | L14: =IF(AND($A14>=Assumptions!$B$24,J14>=0),1,0) -> 0 | M14: =IF($A14=Assumptions!$B$22,Assumptions!$B$21,IF($A14<Assumptions!$B$24,0,IF($A14<=Assumptions!$B$26,Assumptions!$B$25,IF($A14<=Assumptions!$B$28,Assumptions!$B$27,Assumptions!$B$29))*Assumptions!$E$14)) -> 6 | N14: =N13*(1-Assumptions!$E$12)+M14 -> 23.176609 | O14: =N14*Assumptions!$E$10*Assumptions!$E$11+IF($A14=Assumptions!$B$22,Assumptions!$B$21*Assumptions!$B$23,0)-Assumptions!$E$18-M14*Assumptions!$E$13-$B14 -> -5783.228 | P14: =P13+O14 -> -53321.827 | Q14: =IF(AND($A14>=Assumptions!$B$24,O14>=0),1,0) -> 0 | R14: =IF($A14=Assumptions!$B$22,Assumptions!$B$21,IF($A14<Assumptions!$B$24,0,IF($A14<=Assumptions!$B$26,Assumptions!$B$25,IF($A14<=Assumptions!$B$28,Assumptions!$B$27,Assumptions!$B$29))*Assumptions!$F$14)) -> 4 | S14: =S13*(1-Assumptions!$F$12)+R14 -> 16.955357 | T14: =S14*Assumptions!$F$10*Assumptions!$F$11+IF($A14=Assumptions!$B$22,Assumptions!$B$21*Assumptions!$B$23,0)-Assumptions!$F$18-R14*Assumptions!$F$13-$B14 -> -1864.1741 | U14: =U13+T14 -> -17258.37 | V14: =IF(AND($A14>=Assumptions!$B$24,T14>=0),1,0) -> 0 | W14: =IF($A14=Assumptions!$B$22,Assumptions!$B$21,IF($A14<Assumptions!$B$24,0,IF($A14<=Assumptions!$B$26,Assumptions!$B$25,IF($A14<=Assumptions!$B$28,Assumptions!$B$27,Assumptions!$B$29))*Assumptions!$G$14)) -> 4 | X14: =X13*(1-Assumptions!$G$12)+W14 -> 16.955357 | Y14: =X14*Assumptions!$G$10*Assumptions!$G$11+IF($A14=Assumptions!$B$22,Assumptions!$B$21*Assumptions!$B$23,0)-Assumptions!$G$18-W14*Assumptions!$G$13-$B14 -> -5864.1741 | Z14: =Z13+Y14 -> -53258.37 | AA14: =IF(AND($A14>=Assumptions!$B$24,Y14>=0),1,0) -> 0
A15: 10 | B15: =SUMIF(Assumptions!$B$33:$B$38,A15,Assumptions!$C$33:$C$38) -> 0 | C15: =IF($A15=Assumptions!$B$22,Assumptions!$B$21,IF($A15<Assumptions!$B$24,0,IF($A15<=Assumptions!$B$26,Assumptions!$B$25,IF($A15<=Assumptions!$B$28,Assumptions!$B$27,Assumptions!$B$29))*Assumptions!$C$14)) -> 2 | D15: =D14*(1-Assumptions!$C$12)+C15 -> 12.062436 | E15: =D15*Assumptions!$C$10*Assumptions!$C$11+IF($A15=Assumptions!$B$22,Assumptions!$B$21*Assumptions!$B$23,0)-Assumptions!$C$18-C15*Assumptions!$C$13-$B15 -> -5938.1269 | F15: =F14+E15 -> -60275.588 | G15: =IF(AND($A15>=Assumptions!$B$24,E15>=0),1,0) -> 0 | H15: =IF($A15=Assumptions!$B$22,Assumptions!$B$21,IF($A15<Assumptions!$B$24,0,IF($A15<=Assumptions!$B$26,Assumptions!$B$25,IF($A15<=Assumptions!$B$28,Assumptions!$B$27,Assumptions!$B$29))*Assumptions!$D$14)) -> 4 | I15: =I14*(1-Assumptions!$D$12)+H15 -> 20.446696 | J15: =I15*Assumptions!$D$10*Assumptions!$D$11+IF($A15=Assumptions!$B$22,Assumptions!$B$21*Assumptions!$B$23,0)-Assumptions!$D$18-H15*Assumptions!$D$13-$B15 -> -5733.2489 | K15: =K14+J15 -> -58991.619 | L15: =IF(AND($A15>=Assumptions!$B$24,J15>=0),1,0) -> 0 | M15: =IF($A15=Assumptions!$B$22,Assumptions!$B$21,IF($A15<Assumptions!$B$24,0,IF($A15<=Assumptions!$B$26,Assumptions!$B$25,IF($A15<=Assumptions!$B$28,Assumptions!$B$27,Assumptions!$B$29))*Assumptions!$E$14)) -> 6 | N15: =N14*(1-Assumptions!$E$12)+M15 -> 28.713077 | O15: =N15*Assumptions!$E$10*Assumptions!$E$11+IF($A15=Assumptions!$B$22,Assumptions!$B$21*Assumptions!$B$23,0)-Assumptions!$E$18-M15*Assumptions!$E$13-$B15 -> -5492.5635 | P15: =P14+O15 -> -58814.39 | Q15: =IF(AND($A15>=Assumptions!$B$24,O15>=0),1,0) -> 0 | R15: =IF($A15=Assumptions!$B$22,Assumptions!$B$21,IF($A15<Assumptions!$B$24,0,IF($A15<=Assumptions!$B$26,Assumptions!$B$25,IF($A15<=Assumptions!$B$28,Assumptions!$B$27,Assumptions!$B$29))*Assumptions!$F$14)) -> 4 | S15: =S14*(1-Assumptions!$F$12)+R15 -> 20.446696 | T15: =S15*Assumptions!$F$10*Assumptions!$F$11+IF($A15=Assumptions!$B$22,Assumptions!$B$21*Assumptions!$B$23,0)-Assumptions!$F$18-R15*Assumptions!$F$13-$B15 -> -1733.2489 | U15: =U14+T15 -> -18991.619 | V15: =IF(AND($A15>=Assumptions!$B$24,T15>=0),1,0) -> 0 | W15: =IF($A15=Assumptions!$B$22,Assumptions!$B$21,IF($A15<Assumptions!$B$24,0,IF($A15<=Assumptions!$B$26,Assumptions!$B$25,IF($A15<=Assumptions!$B$28,Assumptions!$B$27,Assumptions!$B$29))*Assumptions!$G$14)) -> 4 | X15: =X14*(1-Assumptions!$G$12)+W15 -> 20.446696 | Y15: =X15*Assumptions!$G$10*Assumptions!$G$11+IF($A15=Assumptions!$B$22,Assumptions!$B$21*Assumptions!$B$23,0)-Assumptions!$G$18-W15*Assumptions!$G$13-$B15 -> -5733.2489 | Z15: =Z14+Y15 -> -58991.619 | AA15: =IF(AND($A15>=Assumptions!$B$24,Y15>=0),1,0) -> 0
A16: 11 | B16: =SUMIF(Assumptions!$B$33:$B$38,A16,Assumptions!$C$33:$C$38) -> 0 | C16: =IF($A16=Assumptions!$B$22,Assumptions!$B$21,IF($A16<Assumptions!$B$24,0,IF($A16<=Assumptions!$B$26,Assumptions!$B$25,IF($A16<=Assumptions!$B$28,Assumptions!$B$27,Assumptions!$B$29))*Assumptions!$C$14)) -> 2 | D16: =D15*(1-Assumptions!$C$12)+C16 -> 13.459314 | E16: =D16*Assumptions!$C$10*Assumptions!$C$11+IF($A16=Assumptions!$B$22,Assumptions!$B$21*Assumptions!$B$23,0)-Assumptions!$C$18-C16*Assumptions!$C$13-$B16 -> -5896.2206 | F16: =F15+E16 -> -66171.809 | G16: =IF(AND($A16>=Assumptions!$B$24,E16>=0),1,0) -> 0 | H16: =IF($A16=Assumptions!$B$22,Assumptions!$B$21,IF($A16<Assumptions!$B$24,0,IF($A16<=Assumptions!$B$26,Assumptions!$B$25,IF($A16<=Assumptions!$B$28,Assumptions!$B$27,Assumptions!$B$29))*Assumptions!$D$14)) -> 4 | I16: =I15*(1-Assumptions!$D$12)+H16 -> 23.833295 | J16: =I16*Assumptions!$D$10*Assumptions!$D$11+IF($A16=Assumptions!$B$22,Assumptions!$B$21*Assumptions!$B$23,0)-Assumptions!$D$18-H16*Assumptions!$D$13-$B16 -> -5606.2514 | K16: =K15+J16 -> -64597.871 | L16: =IF(AND($A16>=Assumptions!$B$24,J16>=0),1,0) -> 0 | M16: =IF($A16=Assumptions!$B$22,Assumptions!$B$21,IF($A16<Assumptions!$B$24,0,IF($A16<=Assumptions!$B$26,Assumptions!$B$25,IF($A16<=Assumptions!$B$28,Assumptions!$B$27,Assumptions!$B$29))*Assumptions!$E$14)) -> 6 | N16: =N15*(1-Assumptions!$E$12)+M16 -> 34.138815 | O16: =N16*Assumptions!$E$10*Assumptions!$E$11+IF($A16=Assumptions!$B$22,Assumptions!$B$21*Assumptions!$B$23,0)-Assumptions!$E$18-M16*Assumptions!$E$13-$B16 -> -5207.7122 | P16: =P15+O16 -> -64022.102 | Q16: =IF(AND($A16>=Assumptions!$B$24,O16>=0),1,0) -> 0 | R16: =IF($A16=Assumptions!$B$22,Assumptions!$B$21,IF($A16<Assumptions!$B$24,0,IF($A16<=Assumptions!$B$26,Assumptions!$B$25,IF($A16<=Assumptions!$B$28,Assumptions!$B$27,Assumptions!$B$29))*Assumptions!$F$14)) -> 4 | S16: =S15*(1-Assumptions!$F$12)+R16 -> 23.833295 | T16: =S16*Assumptions!$F$10*Assumptions!$F$11+IF($A16=Assumptions!$B$22,Assumptions!$B$21*Assumptions!$B$23,0)-Assumptions!$F$18-R16*Assumptions!$F$13-$B16 -> -1606.2514 | U16: =U15+T16 -> -20597.871 | V16: =IF(AND($A16>=Assumptions!$B$24,T16>=0),1,0) -> 0 | W16: =IF($A16=Assumptions!$B$22,Assumptions!$B$21,IF($A16<Assumptions!$B$24,0,IF($A16<=Assumptions!$B$26,Assumptions!$B$25,IF($A16<=Assumptions!$B$28,Assumptions!$B$27,Assumptions!$B$29))*Assumptions!$G$14)) -> 4 | X16: =X15*(1-Assumptions!$G$12)+W16 -> 23.833295 | Y16: =X16*Assumptions!$G$10*Assumptions!$G$11+IF($A16=Assumptions!$B$22,Assumptions!$B$21*Assumptions!$B$23,0)-Assumptions!$G$18-W16*Assumptions!$G$13-$B16 -> -5606.2514 | Z16: =Z15+Y16 -> -64597.871 | AA16: =IF(AND($A16>=Assumptions!$B$24,Y16>=0),1,0) -> 0
A17: 12 | B17: =SUMIF(Assumptions!$B$33:$B$38,A17,Assumptions!$C$33:$C$38) -> 13000 | C17: =IF($A17=Assumptions!$B$22,Assumptions!$B$21,IF($A17<Assumptions!$B$24,0,IF($A17<=Assumptions!$B$26,Assumptions!$B$25,IF($A17<=Assumptions!$B$28,Assumptions!$B$27,Assumptions!$B$29))*Assumptions!$C$14)) -> 2 | D17: =D16*(1-Assumptions!$C$12)+C17 -> 14.786348 | E17: =D17*Assumptions!$C$10*Assumptions!$C$11+IF($A17=Assumptions!$B$22,Assumptions!$B$21*Assumptions!$B$23,0)-Assumptions!$C$18-C17*Assumptions!$C$13-$B17 -> -18856.41 | F17: =F16+E17 -> -85028.218 | G17: =IF(AND($A17>=Assumptions!$B$24,E17>=0),1,0) -> 0 | H17: =IF($A17=Assumptions!$B$22,Assumptions!$B$21,IF($A17<Assumptions!$B$24,0,IF($A17<=Assumptions!$B$26,Assumptions!$B$25,IF($A17<=Assumptions!$B$28,Assumptions!$B$27,Assumptions!$B$29))*Assumptions!$D$14)) -> 4 | I17: =I16*(1-Assumptions!$D$12)+H17 -> 27.118296 | J17: =I17*Assumptions!$D$10*Assumptions!$D$11+IF($A17=Assumptions!$B$22,Assumptions!$B$21*Assumptions!$B$23,0)-Assumptions!$D$18-H17*Assumptions!$D$13-$B17 -> -18483.064 | K17: =K16+J17 -> -83080.934 | L17: =IF(AND($A17>=Assumptions!$B$24,J17>=0),1,0) -> 0 | M17: =IF($A17=Assumptions!$B$22,Assumptions!$B$21,IF($A17<Assumptions!$B$24,0,IF($A17<=Assumptions!$B$26,Assumptions!$B$25,IF($A17<=Assumptions!$B$28,Assumptions!$B$27,Assumptions!$B$29))*Assumptions!$E$14)) -> 6 | N17: =N16*(1-Assumptions!$E$12)+M17 -> 39.456039 | O17: =N17*Assumptions!$E$10*Assumptions!$E$11+IF($A17=Assumptions!$B$22,Assumptions!$B$21*Assumptions!$B$23,0)-Assumptions!$E$18-M17*Assumptions!$E$13-$B17 -> -17928.558 | P17: =P16+O17 -> -81950.66 | Q17: =IF(AND($A17>=Assumptions!$B$24,O17>=0),1,0) -> 0 | R17: =IF($A17=Assumptions!$B$22,Assumptions!$B$21,IF($A17<Assumptions!$B$24,0,IF($A17<=Assumptions!$B$26,Assumptions!$B$25,IF($A17<=Assumptions!$B$28,Assumptions!$B$27,Assumptions!$B$29))*Assumptions!$F$14)) -> 4 | S17: =S16*(1-Assumptions!$F$12)+R17 -> 27.118296 | T17: =S17*Assumptions!$F$10*Assumptions!$F$11+IF($A17=Assumptions!$B$22,Assumptions!$B$21*Assumptions!$B$23,0)-Assumptions!$F$18-R17*Assumptions!$F$13-$B17 -> -14483.064 | U17: =U16+T17 -> -35080.934 | V17: =IF(AND($A17>=Assumptions!$B$24,T17>=0),1,0) -> 0 | W17: =IF($A17=Assumptions!$B$22,Assumptions!$B$21,IF($A17<Assumptions!$B$24,0,IF($A17<=Assumptions!$B$26,Assumptions!$B$25,IF($A17<=Assumptions!$B$28,Assumptions!$B$27,Assumptions!$B$29))*Assumptions!$G$14)) -> 4 | X17: =X16*(1-Assumptions!$G$12)+W17 -> 27.118296 | Y17: =X17*Assumptions!$G$10*Assumptions!$G$11+IF($A17=Assumptions!$B$22,Assumptions!$B$21*Assumptions!$B$23,0)-Assumptions!$G$18-W17*Assumptions!$G$13-$B17 -> -18483.064 | Z17: =Z16+Y17 -> -83080.934 | AA17: =IF(AND($A17>=Assumptions!$B$24,Y17>=0),1,0) -> 0
