Workbook

Sheet Start Here
A1: Pilot Candidate Tracker
A2: Log prospects, screen them, record interviews, and check the go / no-go rule from the interview plan.
A4: HOW TO USE
A5: 1. Add each prospect on the Tracker sheet, one row each, and fill in the CONTACT columns.
A6: 2. When someone replies, ask the five screener questions (see the screener document). Fill in the SCREENER columns. 'Screener result' fills itself in.
A7: 3. Right after each interview, fill in the INTERVIEW columns while it is fresh.
A8: 4. Open the Funnel sheet weekly for reply rates, follow-ups due, and the decision check.
A10: WHAT TO EDIT
A11: Tracker: type in every column except the three gray-header columns (Follow-up due, Screener result, Funnel stage).
A12: Rules: change the blue numbers on yellow if your criteria change. The lists there feed the dropdowns.
A13: Funnel: nothing to type.
A15: HOW 'SCREENER RESULT' WORKS
A16: ="Qualified: "&Rules!B5&" to "&Rules!B6&" doors, manages at least some for other owners, and willing to do 30 minutes." -> Qualified: 10 to 50 doors, manages at least some for other owners, and willing to do 30 minutes.
A17: ="Maybe: between "&Rules!B7&" and "&Rules!B8&" doors but outside the qualified range, or unsure about the 30 minutes." -> Maybe: between 5 and 100 doors but outside the qualified range, or unsure about the 30 minutes.
A18: ="Not a fit: manages only their own, unwilling to talk, or fewer than "&Rules!B7&" or more than "&Rules!B8&" doors." -> Not a fit: manages only their own, unwilling to talk, or fewer than 5 or more than 100 doors.
A19: Incomplete: fewer than the three screener answers (doors, manages for others, willing) are filled in.
A21: COLUMN GUIDE (with one example prospect)
A22: Column | B22: What to enter | C22: Example
A23: ID | B23: Pre-filled. | C23: P001
A24: Name | B24: The person's name. | C24: Dana Reyes
A25: Business | B25: Company name, or 'Independent'. | C25: Reyes Rentals
A26: Source | B26: Where you found them (dropdown). | C26: Referral: accountant / bookkeeper
A27: Channel | B27: How you first contacted them (dropdown). | C27: Email
A28: Contact info | B28: Email or phone. | C28: dana@example.com
A29: Date first contacted | B29: The date you first reached out. | C29: Oct 1, 2026
A30: Follow-up due (auto) | B30: Calculates: first-contact date plus the follow-up days on Rules, only while Status is 'Contacted'. Turns red when due. | C30: (blank: they have replied)
A31: Status | B31: Where they are now (dropdown). Log people you screen out after they reply as 'Not a fit'. | C31: Scheduled
A32: Doors managed | B32: Number of rentable units, from screener question 1. | C32: 28
A33: Manages for other owners? | B33: Yes, Some, or No (question 2). | C33: Yes
... A48: Funnel stage (auto) | B48: Calculates from Status (see Rules). | C48: 3
A50: NOTES AND ASSUMPTIONS
A51: Thresholds (10-50 doors, 4 of 10 painful workflow, 2-3 paid-pilot yeses, 3-4 day follow-up) come from the interview plan. The wider 'Maybe' band (5-100 doors) is my assumption [hypothesis].
A52: No reply-rate target is built in. The earlier estimate (contact 60-100 cold prospects for 10 interviews) is a hypothesis; the Funnel sheet shows your actual rate.
A53: The Tracker holds 150 prospects (rows 5-154). To add more, insert rows above row 154 and copy the formulas down from the row above.
A54: This file holds personal information. Keep it in a protected folder, get consent before recording calls, and delete records when asked.

Sheet Tracker
A1: Pilot Candidate Tracker
A2: Type in every column except the gray-header ones (Follow-up due, Screener result, Funnel stage), which calculate. Dropdowns are on the coloured-list columns. Rows 5-154 are ready for 150 prospects.
A3: CONTACT | J3: SCREENER | P3: INTERVIEW | V3: FOLLOW-UP | Z3: AUTO
A4: ID | B4: Name | C4: Business | D4: Source | E4: Channel | F4: Contact info | G4: Date first contacted | H4: Follow-up due (auto) | I4: Status | J4: Doors managed | K4: Manages for other owners? | L4: Current tools | M4: Books handled by | N4: Willing to do 30 min? | O4: Screener result (auto) | P4: Interview date | Q4: Described a recent painful workflow? | R4: Needs online rent collection to switch? | S4: Deployment preference | T4: Paid pilot interest | U4: Price named ($/month) | V4: Thank-you sent? | W4: Referrals given | X4: Next action | Y4: Notes | Z4: Funnel stage (auto)
A5: P001 | H5: =IF(AND(G5<>"",I5="Contacted"),G5+Rules!$B$17,"") | O5: =IF(COUNTA(J5,K5,N5)=0,"",IF(COUNTA(J5,K5,N5)<3,"Incomplete",IF(OR(K5="No",N5="No",J5<Rules!$B$7,J5>Rules!$B$8),"Not a fit",IF(AND(J5>=Rules!$B$5,J5<=Rules!$B$6,N5="Yes"),"Qualified","Maybe")))) | Z5: =IF(I5="","",IFERROR(VLOOKUP(I5,Rules!$A$21:$B$30,2,FALSE()),""))
A6: P002 | H6: =IF(AND(G6<>"",I6="Contacted"),G6+Rules!$B$17,"") | O6: =IF(COUNTA(J6,K6,N6)=0,"",IF(COUNTA(J6,K6,N6)<3,"Incomplete",IF(OR(K6="No",N6="No",J6<Rules!$B$7,J6>Rules!$B$8),"Not a fit",IF(AND(J6>=Rules!$B$5,J6<=Rules!$B$6,N6="Yes"),"Qualified","Maybe")))) | Z6: =IF(I6="","",IFERROR(VLOOKUP(I6,Rules!$A$21:$B$30,2,FALSE()),""))
A7: P003 | H7: =IF(AND(G7<>"",I7="Contacted"),G7+Rules!$B$17,"") | O7: =IF(COUNTA(J7,K7,N7)=0,"",IF(COUNTA(J7,K7,N7)<3,"Incomplete",IF(OR(K7="No",N7="No",J7<Rules!$B$7,J7>Rules!$B$8),"Not a fit",IF(AND(J7>=Rules!$B$5,J7<=Rules!$B$6,N7="Yes"),"Qualified","Maybe")))) | Z7: =IF(I7="","",IFERROR(VLOOKUP(I7,Rules!$A$21:$B$30,2,FALSE()),""))
A8: P004 | H8: =IF(AND(G8<>"",I8="Contacted"),G8+Rules!$B$17,"") | O8: =IF(COUNTA(J8,K8,N8)=0,"",IF(COUNTA(J8,K8,N8)<3,"Incomplete",IF(OR(K8="No",N8="No",J8<Rules!$B$7,J8>Rules!$B$8),"Not a fit",IF(AND(J8>=Rules!$B$5,J8<=Rules!$B$6,N8="Yes"),"Qualified","Maybe")))) | Z8: =IF(I8="","",IFERROR(VLOOKUP(I8,Rules!$A$21:$B$30,2,FALSE()),""))
A9: P005 | H9: =IF(AND(G9<>"",I9="Contacted"),G9+Rules!$B$17,"") | O9: =IF(COUNTA(J9,K9,N9)=0,"",IF(COUNTA(J9,K9,N9)<3,"Incomplete",IF(OR(K9="No",N9="No",J9<Rules!$B$7,J9>Rules!$B$8),"Not a fit",IF(AND(J9>=Rules!$B$5,J9<=Rules!$B$6,N9="Yes"),"Qualified","Maybe")))) | Z9: =IF(I9="","",IFERROR(VLOOKUP(I9,Rules!$A$21:$B$30,2,FALSE()),""))
A10: P006 | H10: =IF(AND(G10<>"",I10="Contacted"),G10+Rules!$B$17,"") | O10: =IF(COUNTA(J10,K10,N10)=0,"",IF(COUNTA(J10,K10,N10)<3,"Incomplete",IF(OR(K10="No",N10="No",J10<Rules!$B$7,J10>Rules!$B$8),"Not a fit",IF(AND(J10>=Rules!$B$5,J10<=Rules!$B$6,N10="Yes"),"Qualified","Maybe")))) | Z10: =IF(I10="","",IFERROR(VLOOKUP(I10,Rules!$A$21:$B$30,2,FALSE()),""))
A11: P007 | H11: =IF(AND(G11<>"",I11="Contacted"),G11+Rules!$B$17,"") | O11: =IF(COUNTA(J11,K11,N11)=0,"",IF(COUNTA(J11,K11,N11)<3,"Incomplete",IF(OR(K11="No",N11="No",J11<Rules!$B$7,J11>Rules!$B$8),"Not a fit",IF(AND(J11>=Rules!$B$5,J11<=Rules!$B$6,N11="Yes"),"Qualified","Maybe")))) | Z11: =IF(I11="","",IFERROR(VLOOKUP(I11,Rules!$A$21:$B$30,2,FALSE()),""))
A12: P008 | H12: =IF(AND(G12<>"",I12="Contacted"),G12+Rules!$B$17,"") | O12: =IF(COUNTA(J12,K12,N12)=0,"",IF(COUNTA(J12,K12,N12)<3,"Incomplete",IF(OR(K12="No",N12="No",J12<Rules!$B$7,J12>Rules!$B$8),"Not a fit",IF(AND(J12>=Rules!$B$5,J12<=Rules!$B$6,N12="Yes"),"Qualified","Maybe")))) | Z12: =IF(I12="","",IFERROR(VLOOKUP(I12,Rules!$A$21:$B$30,2,FALSE()),""))
A13: P009 | H13: =IF(AND(G13<>"",I13="Contacted"),G13+Rules!$B$17,"") | O13: =IF(COUNTA(J13,K13,N13)=0,"",IF(COUNTA(J13,K13,N13)<3,"Incomplete",IF(OR(K13="No",N13="No",J13<Rules!$B$7,J13>Rules!$B$8),"Not a fit",IF(AND(J13>=Rules!$B$5,J13<=Rules!$B$6,N13="Yes"),"Qualified","Maybe")))) | Z13: =IF(I13="","",IFERROR(VLOOKUP(I13,Rules!$A$21:$B$30,2,FALSE()),""))
A14: P010 | H14: =IF(AND(G14<>"",I14="Contacted"),G14+Rules!$B$17,"") | O14: =IF(COUNTA(J14,K14,N14)=0,"",IF(COUNTA(J14,K14,N14)<3,"Incomplete",IF(OR(K14="No",N14="No",J14<Rules!$B$7,J14>Rules!$B$8),"Not a fit",IF(AND(J14>=Rules!$B$5,J14<=Rules!$B$6,N14="Yes"),"Qualified","Maybe")))) | Z14: =IF(I14="","",IFERROR(VLOOKUP(I14,Rules!$A$21:$B$30,2,FALSE()),""))
A15: P011 | H15: =IF(AND(G15<>"",I15="Contacted"),G15+Rules!$B$17,"") | O15: =IF(COUNTA(J15,K15,N15)=0,"",IF(COUNTA(J15,K15,N15)<3,"Incomplete",IF(OR(K15="No",N15="No",J15<Rules!$B$7,J15>Rules!$B$8),"Not a fit",IF(AND(J15>=Rules!$B$5,J15<=Rules!$B$6,N15="Yes"),"Qualified","Maybe")))) | Z15: =IF(I15="","",IFERROR(VLOOKUP(I15,Rules!$A$21:$B$30,2,FALSE()),""))
A16: P012 | H16: =IF(AND(G16<>"",I16="Contacted"),G16+Rules!$B$17,"") | O16: =IF(COUNTA(J16,K16,N16)=0,"",IF(COUNTA(J16,K16,N16)<3,"Incomplete",IF(OR(K16="No",N16="No",J16<Rules!$B$7,J16>Rules!$B$8),"Not a fit",IF(AND(J16>=Rules!$B$5,J16<=Rules!$B$6,N16="Yes"),"Qualified","Maybe")))) | Z16: =IF(I16="","",IFERROR(VLOOKUP(I16,Rules!$A$21:$B$30,2,FALSE()),""))
... A154: P150 | H154: =IF(AND(G154<>"",I154="Contacted"),G154+Rules!$B$17,"") | O154: =IF(COUNTA(J154,K154,N154)=0,"",IF(COUNTA(J154,K154,N154)<3,"Incomplete",IF(OR(K154="No",N154="No",J154<Rules!$B$7,J154>Rules!$B$8),"Not a fit",IF(AND(J154>=Rules!$B$5,J154<=Rules!$B$6,N154="Yes"),"Qualified","Maybe")))) | Z154: =IF(I154="","",IFERROR(VLOOKUP(I154,Rules!$A$21:$B$30,2,FALSE()),""))

Sheet Funnel
A1: Funnel & Decision Check
A2: Everything here calculates from the Tracker. Nothing to type.
A4: OUTREACH FUNNEL
A5: Stage | B5: Count | C5: % of contacted | D5: % of previous stage
A6: Prospects logged | B6: =COUNTA(Tracker!$B$5:$B$154) -> 0 | C6: - | D6: -
A7: Contacted | B7: =COUNTIF(Tracker!$Z$5:$Z$154,">=1") -> 0 | C7: =IFERROR(B7/$B$7,"-") -> - | D7: =IFERROR(B7/B6,"-") -> -
A8: Replied | B8: =COUNTIF(Tracker!$Z$5:$Z$154,">=2") -> 0 | C8: =IFERROR(B8/$B$7,"-") -> - | D8: =IFERROR(B8/B7,"-") -> -
A9: Interview scheduled | B9: =COUNTIF(Tracker!$Z$5:$Z$154,">=3") -> 0 | C9: =IFERROR(B9/$B$7,"-") -> - | D9: =IFERROR(B9/B8,"-") -> -
A10: Interviewed | B10: =COUNTIF(Tracker!$Z$5:$Z$154,">=4") -> 0 | C10: =IFERROR(B10/$B$7,"-") -> - | D10: =IFERROR(B10/B9,"-") -> -
A11: Pilot offered | B11: =COUNTIF(Tracker!$Z$5:$Z$154,">=5") -> 0 | C11: =IFERROR(B11/$B$7,"-") -> - | D11: =IFERROR(B11/B10,"-") -> -
A12: Pilot signed | B12: =COUNTIF(Tracker!$Z$5:$Z$154,">=6") -> 0 | C12: =IFERROR(B12/$B$7,"-") -> - | D12: =IFERROR(B12/B11,"-") -> -
A14: Contacts per completed interview | B14: =IFERROR(B7/B10,"-") -> -
A15: Follow-ups due today or overdue | B15: =COUNTIF(Tracker!$H$5:$H$154,"<="&TODAY()) -> 0
A17: DECISION CHECK (from the interview plan)
A18: Measure | B18: Actual | C18: Needed | D18: Met?
A19: Interviews completed | B19: =B10 -> 0 | C19: =Rules!B11 -> 10 | D19: =IF(B19>=C19,"Yes","Not yet") -> Not yet
A20: Described a recent painful workflow | B20: =COUNTIFS(Tracker!$Q$5:$Q$154,"Yes",Tracker!$Z$5:$Z$154,">=4") -> 0 | C20: =Rules!B12 -> 4 | D20: =IF(B20>=C20,"Yes","Not yet") -> Not yet
A21: Said yes to a paid pilot | B21: =COUNTIFS(Tracker!$T$5:$T$154,"Yes",Tracker!$Z$5:$Z$154,">=4") -> 0 | C21: =Rules!B13 -> 2 | D21: =IF(B21>=C21,"Yes","Not yet") -> Not yet
A22: Result | B22: =IF(D19="Not yet","Keep interviewing ("&(C19-B19)&" to go)",IF(AND(D20="Yes",D21="Yes"),"Rule met: proceed to pilots","Rule not met: review findings before building")) -> Keep interviewing (10 to go)
A23: Uses counts. If you interview more than the number needed, raise the minimums on the Rules sheet proportionally.
A25: SIGNAL: ONLINE RENT COLLECTION (interviewed only)
A26: Interviewed who need online rent collection | B26: =COUNTIFS(Tracker!$R$5:$R$154,"Yes",Tracker!$Z$5:$Z$154,">=4") -> 0
A27: Share of interviewed | B27: =IFERROR(B26/B10,"-") -> -
A28: Signal | B28: =IF(B10=0,"-",IF(B27>Rules!B14,"Most say yes: consider scoping payments earlier (roadmap stop signal)","Not a majority")) -> -
A30: DEPLOYMENT PREFERENCE (interviewed only)
A31: Option | B31: Count | C31: % of interviewed
A32: =Rules!K21 -> Hosted | B32: =COUNTIFS(Tracker!$S$5:$S$154,A32,Tracker!$Z$5:$Z$154,">=4") -> 0 | C32: =IFERROR(B32/$B$10,"-") -> -
A33: =Rules!K22 -> Local | B33: =COUNTIFS(Tracker!$S$5:$S$154,A33,Tracker!$Z$5:$Z$154,">=4") -> 0 | C33: =IFERROR(B33/$B$10,"-") -> -
A34: =Rules!K23 -> Either | B34: =COUNTIFS(Tracker!$S$5:$S$154,A34,Tracker!$Z$5:$Z$154,">=4") -> 0 | C34: =IFERROR(B34/$B$10,"-") -> -
A35: =Rules!K24 -> Unsure | B35: =COUNTIFS(Tracker!$S$5:$S$154,A35,Tracker!$Z$5:$Z$154,">=4") -> 0 | C35: =IFERROR(B35/$B$10,"-") -> -
A36: Stated preference is a signal, not behavior (roadmap Phase 0 checkpoint).
A38: PRICE NAMED ($/MONTH)
A39: Median | B39: =IFERROR(MEDIAN(Tracker!$U$5:$U$154),"-") -> -
A40: Average | B40: =IFERROR(AVERAGE(Tracker!$U$5:$U$154),"-") -> -
A41: Responses | B41: =COUNT(Tracker!$U$5:$U$154) -> 0
A43: BY SOURCE
A44: Source | B44: Logged | C44: Contacted | D44: Replied | E44: Interviewed | F44: Reply rate
A45: =Rules!D21 -> Referral: accountant / bookkeeper | B45: =COUNTIF(Tracker!$D$5:$D$154,A45) -> 0 | C45: =COUNTIFS(Tracker!$D$5:$D$154,A45,Tracker!$Z$5:$Z$154,">=1") -> 0 | D45: =COUNTIFS(Tracker!$D$5:$D$154,A45,Tracker!$Z$5:$Z$154,">=2") -> 0 | E45: =COUNTIFS(Tracker!$D$5:$D$154,A45,Tracker!$Z$5:$Z$154,">=4") -> 0 | F45: =IFERROR(D45/C45,"-") -> -
A46: =Rules!D22 -> Referral: contractor / vendor | B46: =COUNTIF(Tracker!$D$5:$D$154,A46) -> 0 | C46: =COUNTIFS(Tracker!$D$5:$D$154,A46,Tracker!$Z$5:$Z$154,">=1") -> 0 | D46: =COUNTIFS(Tracker!$D$5:$D$154,A46,Tracker!$Z$5:$Z$154,">=2") -> 0 | E46: =COUNTIFS(Tracker!$D$5:$D$154,A46,Tracker!$Z$5:$Z$154,">=4") -> 0 | F46: =IFERROR(D46/C46,"-") -> -
A47: =Rules!D23 -> Referral: agent / broker / lender | B47: =COUNTIF(Tracker!$D$5:$D$154,A47) -> 0 | C47: =COUNTIFS(Tracker!$D$5:$D$154,A47,Tracker!$Z$5:$Z$154,">=1") -> 0 | D47: =COUNTIFS(Tracker!$D$5:$D$154,A47,Tracker!$Z$5:$Z$154,">=2") -> 0 | E47: =COUNTIFS(Tracker!$D$5:$D$154,A47,Tracker!$Z$5:$Z$154,">=4") -> 0 | F47: =IFERROR(D47/C47,"-") -> -
...

Sheet Rules
A1: Rules & Lists
A2: Blue numbers on a yellow fill are inputs you can change. Everything else in the workbook reads from this sheet.
A4: SCREENER THRESHOLDS
A5: Qualified: minimum doors | B5: 10 | C5: Interview plan targets managers with about 10-50 doors.
A6: Qualified: maximum doors | B6: 50 | C6: Interview plan (same range).
A7: Maybe: lowest doors considered | B7: 5 | C7: My assumption [hypothesis]: a wider band worth a conversation.
A8: Maybe: highest doors considered | B8: 100 | C8: My assumption [hypothesis]. Larger operators are skipped.
A10: DECISION RULE
A11: Interviews needed before deciding | B11: 10 | C11: Interview plan: 'at least 4 of 10 interviewees'.
A12: Minimum interviewees describing a recent painful workflow | B12: 4 | C12: Interview plan decision rule [hypothesis].
A13: Minimum interviewees saying yes to a paid pilot | B13: 2 | C13: Interview plan says 2-3 [hypothesis]. Set to 3 for a stricter test.
A14: Share that counts as 'most' (rent-collection signal) | B14: 0.5 | C14: Signal fires when the share is above this. Roadmap stop signal.
A16: OUTREACH
A17: Follow-up after first contact (days) | B17: 4 | C17: Outreach plan: follow up once after 3-4 days.
A19: LISTS (used by the dropdowns)
A20: Status | B20: Funnel stage (do not change) | D20: Source | F20: Channel | H20: Yes / Some / No | I20: Yes / Unsure / No | J20: Books handled by | K20: Deployment preference | L20: Yes / Maybe / No | M20: Yes / No
A21: To contact | B21: 0 | D21: Referral: accountant / bookkeeper | F21: Email | H21: Yes | I21: Yes | J21: Self | K21: Hosted | L21: Yes | M21: Yes
A22: Contacted | B22: 1 | D22: Referral: contractor / vendor | F22: Phone | H22: Some | I22: Unsure | J22: Bookkeeper | K22: Local | L22: Maybe | M22: No
A23: No response | B23: 1 | D23: Referral: agent / broker / lender | F23: Text | H23: No | I23: No | J23: Accountant / CPA | K23: Either | L23: No
A24: Replied | B24: 2 | D24: Referral: interviewee | F24: LinkedIn message | J24: Staff | K24: Unsure
A25: Declined | B25: 2 | D25: Personal network | F25: Forum / DM | J25: Other
A26: Not a fit | B26: 2 | D26: NARPM | F26: In person
A27: Scheduled | B27: 3 | D27: Investor association (REIA) | F27: Other
A28: Interviewed | B28: 4 | D28: Landlord / apartment association
A29: Pilot offered | B29: 5 | D29: BiggerPockets
A30: Pilot signed | B30: 6 | D30: Reddit
D31: Facebook group
D32: LinkedIn
D33: Google Maps / Yelp
D34: State license lookup
D35: Other
A37: To add a dropdown option, insert a row inside the list (not below it) so the dropdown range grows. If you rename an option, update existing Tracker rows that use it.
A38: Funnel stage numbers: 1 = contacted, 2 = replied, 3 = scheduled, 4 = interviewed, 5 = pilot offered, 6 = pilot signed.
